<robot name="robotiq-3f-gripper_articulated">
  <link name="finger_1_link_0">
    <visual>
      <origin rpy="0 0 0" xyz="0.020 0 0" />
      <geometry>
        <mesh filename="meshes/visual/link_0.dae" />
      </geometry>
      <material name="0">
        <color rgba="0 1 0 1" />
      </material>
    </visual>
    <collision>
      <origin rpy="0 3.1416 -1.57" xyz="-0.0455 0.0414 0.036" />
      <geometry>
        <mesh filename="meshes/collision/link_0.STL" />
      </geometry>
      <material name="1">
        <color rgba="0 1 1 1" />
      </material>
    </collision>
    <inertial>
      <origin rpy="0 0 0" xyz="0 0 0" />
      <mass value="0.05" />
      <inertia ixx="0.01" ixy="-0.00002" ixz="0.00001" iyy="0.0008" iyz="0" izz="0.001" />
    </inertial>
  </link>
  <link name="finger_1_link_1">
    <visual>
      <origin rpy="0 0 -0.52" xyz="0.050 -.028 0" />
      <geometry>
        <mesh filename="meshes/visual/link_1.dae" />
      </geometry>
      <material name="2" />
    </visual>
    <collision>
      <origin rpy="0 0 -0.52" xyz="0.050 -.028 0" />
      <geometry>
        <mesh filename="meshes/collision/link_1.STL" />
      </geometry>
      <material name="3" />
    </collision>
    <inertial>
      <origin rpy="0 0 0" xyz="0 0 0" />
      <mass value="0.15" />
      <inertia ixx="0.001859" ixy="-0.000376" ixz="0.000028" iyy="0.012756" iyz="0" izz="0.0024" />
    </inertial>
  </link>
  <link name="finger_1_link_2">
    
    <visual>
      <origin rpy="0 0 0" xyz="0.039 0 0.0075" />
      <geometry>
        <mesh filename="meshes/visual/link_2.dae" />
      </geometry>
      <material name="4" />
    </visual>
    <collision>
      <origin rpy="0 0 0" xyz="0.039 0 0.0075" />
      <geometry>
        <mesh filename="meshes/collision/link_2.STL" />
      </geometry>
      <material name="5" />
    </collision>
    <inertial>
      <origin rpy="0 0 0" xyz="0 0 0" />
      <mass value="0.15" />
      <inertia ixx="0.001859" ixy="-0.000376" ixz="0.000028" iyy="0.012756" iyz="0" izz="0.0024" />
    </inertial>
  </link>
  <link name="finger_1_link_3">
    <visual>
      <origin rpy="0 0 0.52" xyz="0 0 0" />
      <geometry>
        <mesh filename="meshes/visual/link_3.dae" />
      </geometry>
      <material name="6" />
    </visual>
    <collision>
      <origin rpy="0 0 0.52" xyz="0 0 0" />
      <geometry>
        <mesh filename="meshes/collision/link_3.STL" />
      </geometry>
      <material name="7" />
    </collision>
    <inertial>
      <origin rpy="0 0 0" xyz="0 0 0" />
      <mass value="0.05" />
      <inertia ixx="0.001239" ixy="-0.000251" ixz="0.000019" iyy="0.00085" iyz="0" izz="0.001632" />
    </inertial>
  </link>
  <joint name="finger_1_joint_1" type="revolute">
    <parent link="finger_1_link_0" />
    <child link="finger_1_link_1" />
    <axis xyz="0 0 1" />
    <origin rpy="0 0 0" xyz="0.020 0 0" />
    <limit effort="100" lower="0" upper="3.1416" velocity="100" />
  </joint>
  <joint name="finger_1_joint_2" type="revolute">
    <parent link="finger_1_link_1" />
    <child link="finger_1_link_2" />
    <axis xyz="0 0 1" />
    <origin rpy="0 0 -0.52" xyz="0.050 -.028 0" />
    <limit effort="100" lower="0" upper="3.1416" velocity="100" />
  </joint>
  <joint name="finger_1_joint_3" type="revolute">
    <parent link="finger_1_link_2" />
    <child link="finger_1_link_3" />
    <axis xyz="0 0 1" />
    <origin rpy="0 0 0" xyz="0.039 0 0" />
    <limit effort="100" lower="0" upper="3.1416" velocity="100" />
  </joint>
  <link name="finger_2_link_0">
    <visual>
      <origin rpy="0 0 0" xyz="0.020 0 0" />
      <geometry>
        <mesh filename="meshes/visual/link_0.dae" />
      </geometry>
      <material name="8">
        <color rgba="0 1 0 1" />
      </material>
    </visual>
    <collision>
      <origin rpy="0 3.1416 -1.57" xyz="-0.0455 0.0414 0.036" />
      <geometry>
        <mesh filename="meshes/collision/link_0.STL" />
      </geometry>
      <material name="9">
        <color rgba="0 1 1 1" />
      </material>
    </collision>
    <inertial>
      <origin rpy="0 0 0" xyz="0 0 0" />
      <mass value="0.05" />
      <inertia ixx="0.01" ixy="-0.00002" ixz="0.00001" iyy="0.0008" iyz="0" izz="0.001" />
    </inertial>
  </link>
  <link name="finger_2_link_1">
    <visual>
      <origin rpy="0 0 -0.52" xyz="0.050 -.028 0" />
      <geometry>
        <mesh filename="meshes/visual/link_1.dae" />
      </geometry>
      <material name="10" />
    </visual>
    <collision>
      <origin rpy="0 0 -0.52" xyz="0.050 -.028 0" />
      <geometry>
        <mesh filename="meshes/collision/link_1.STL" />
      </geometry>
      <material name="11" />
    </collision>
    <inertial>
      <origin rpy="0 0 0" xyz="0 0 0" />
      <mass value="0.15" />
      <inertia ixx="0.001859" ixy="-0.000376" ixz="0.000028" iyy="0.012756" iyz="0" izz="0.0024" />
    </inertial>
  </link>
  <link name="finger_2_link_2">
    
    <visual>
      <origin rpy="0 0 0" xyz="0.039 0 0.0075" />
      <geometry>
        <mesh filename="meshes/visual/link_2.dae" />
      </geometry>
      <material name="12" />
    </visual>
    <collision>
      <origin rpy="0 0 0" xyz="0.039 0 0.0075" />
      <geometry>
        <mesh filename="meshes/collision/link_2.STL" />
      </geometry>
      <material name="13" />
    </collision>
    <inertial>
      <origin rpy="0 0 0" xyz="0 0 0" />
      <mass value="0.15" />
      <inertia ixx="0.001859" ixy="-0.000376" ixz="0.000028" iyy="0.012756" iyz="0" izz="0.0024" />
    </inertial>
  </link>
  <link name="finger_2_link_3">
    <visual>
      <origin rpy="0 0 0.52" xyz="0 0 0" />
      <geometry>
        <mesh filename="meshes/visual/link_3.dae" />
      </geometry>
      <material name="14" />
    </visual>
    <collision>
      <origin rpy="0 0 0.52" xyz="0 0 0" />
      <geometry>
        <mesh filename="meshes/collision/link_3.STL" />
      </geometry>
      <material name="15" />
    </collision>
    <inertial>
      <origin rpy="0 0 0" xyz="0 0 0" />
      <mass value="0.05" />
      <inertia ixx="0.001239" ixy="-0.000251" ixz="0.000019" iyy="0.00085" iyz="0" izz="0.001632" />
    </inertial>
  </link>
  <joint name="finger_2_joint_1" type="revolute">
    <parent link="finger_2_link_0" />
    <child link="finger_2_link_1" />
    <axis xyz="0 0 1" />
    <origin rpy="0 0 0" xyz="0.020 0 0" />
    <limit effort="100" lower="0" upper="3.1416" velocity="100" />
  </joint>
  <joint name="finger_2_joint_2" type="revolute">
    <parent link="finger_2_link_1" />
    <child link="finger_2_link_2" />
    <axis xyz="0 0 1" />
    <origin rpy="0 0 -0.52" xyz="0.050 -.028 0" />
    <limit effort="100" lower="0" upper="3.1416" velocity="100" />
  </joint>
  <joint name="finger_2_joint_3" type="revolute">
    <parent link="finger_2_link_2" />
    <child link="finger_2_link_3" />
    <axis xyz="0 0 1" />
    <origin rpy="0 0 0" xyz="0.039 0 0" />
    <limit effort="100" lower="0" upper="3.1416" velocity="100" />
  </joint>
  <link name="finger_middle_link_0">
    <visual>
      <origin rpy="0 0 0" xyz="0.020 0 0" />
      <geometry>
        <mesh filename="meshes/visual/link_0.dae" />
      </geometry>
      <material name="16">
        <color rgba="0 1 0 1" />
      </material>
    </visual>
    <collision>
      <origin rpy="0 3.1416 -1.57" xyz="-0.0455 0.0414 0.036" />
      <geometry>
        <mesh filename="meshes/collision/link_0.STL" />
      </geometry>
      <material name="17">
        <color rgba="0 1 1 1" />
      </material>
    </collision>
    <inertial>
      <origin rpy="0 0 0" xyz="0 0 0" />
      <mass value="0.05" />
      <inertia ixx="0.01" ixy="-0.00002" ixz="0.00001" iyy="0.0008" iyz="0" izz="0.001" />
    </inertial>
  </link>
  <link name="finger_middle_link_1">
    <visual>
      <origin rpy="0 0 -0.52" xyz="0.050 -.028 0" />
      <geometry>
        <mesh filename="meshes/visual/link_1.dae" />
      </geometry>
      <material name="18" />
    </visual>
    <collision>
      <origin rpy="0 0 -0.52" xyz="0.050 -.028 0" />
      <geometry>
        <mesh filename="meshes/collision/link_1.STL" />
      </geometry>
      <material name="19" />
    </collision>
    <inertial>
      <origin rpy="0 0 0" xyz="0 0 0" />
      <mass value="0.15" />
      <inertia ixx="0.001859" ixy="-0.000376" ixz="0.000028" iyy="0.012756" iyz="0" izz="0.0024" />
    </inertial>
  </link>
  <link name="finger_middle_link_2">
    
    <visual>
      <origin rpy="0 0 0" xyz="0.039 0 0.0075" />
      <geometry>
        <mesh filename="meshes/visual/link_2.dae" />
      </geometry>
      <material name="20" />
    </visual>
    <collision>
      <origin rpy="0 0 0" xyz="0.039 0 0.0075" />
      <geometry>
        <mesh filename="meshes/collision/link_2.STL" />
      </geometry>
      <material name="21" />
    </collision>
    <inertial>
      <origin rpy="0 0 0" xyz="0 0 0" />
      <mass value="0.15" />
      <inertia ixx="0.001859" ixy="-0.000376" ixz="0.000028" iyy="0.012756" iyz="0" izz="0.0024" />
    </inertial>
  </link>
  <link name="finger_middle_link_3">
    <visual>
      <origin rpy="0 0 0.52" xyz="0 0 0" />
      <geometry>
        <mesh filename="meshes/visual/link_3.dae" />
      </geometry>
      <material name="22" />
    </visual>
    <collision>
      <origin rpy="0 0 0.52" xyz="0 0 0" />
      <geometry>
        <mesh filename="meshes/collision/link_3.STL" />
      </geometry>
      <material name="23" />
    </collision>
    <inertial>
      <origin rpy="0 0 0" xyz="0 0 0" />
      <mass value="0.05" />
      <inertia ixx="0.001239" ixy="-0.000251" ixz="0.000019" iyy="0.00085" iyz="0" izz="0.001632" />
    </inertial>
  </link>
  <joint name="finger_middle_joint_1" type="revolute">
    <parent link="finger_middle_link_0" />
    <child link="finger_middle_link_1" />
    <axis xyz="0 0 1" />
    <origin rpy="0 0 0" xyz="0.020 0 0" />
    <limit effort="100" lower="0" upper="3.1416" velocity="100" />
  </joint>
  <joint name="finger_middle_joint_2" type="revolute">
    <parent link="finger_middle_link_1" />
    <child link="finger_middle_link_2" />
    <axis xyz="0 0 1" />
    <origin rpy="0 0 -0.52" xyz="0.050 -.028 0" />
    <limit effort="100" lower="0" upper="3.1416" velocity="100" />
  </joint>
  <joint name="finger_middle_joint_3" type="revolute">
    <parent link="finger_middle_link_2" />
    <child link="finger_middle_link_3" />
    <axis xyz="0 0 1" />
    <origin rpy="0 0 0" xyz="0.039 0 0" />
    <limit effort="100" lower="0" upper="3.1416" velocity="100" />
  </joint>
  <link name="palm">
    <visual>
      <geometry>
        <mesh filename="meshes/visual/palm.dae" />
      </geometry>
      <material name="24">
        <color rgba="0 1 0 1" />
      </material>
    </visual>
    <collision>
      <geometry>
        <mesh filename="meshes/collision/palm.STL" />
      </geometry>
      <material name="25">
        <color rgba="0 1 1 1" />
      </material>
    </collision>
  </link>
  <inertial>
    <origin rpy="0 0 0" xyz="0 0 0" />
    <mass value="1.3" />
    <inertia ixx="0.006012" ixy="0.000079" ixz="-0.00024" iyy="0.012892" iyz="0" izz="0.002435" />
  </inertial>
  <joint name="palm_finger_1_joint" type="revolute">
    <parent link="palm" />
    <child link="finger_1_link_0" />
    <axis xyz="0 1 0" />
    <origin rpy="0 3.1416 -1.57" xyz="-0.0455 0.0214 0.036" />
    <limit effort="100" lower="-0.16" upper="0.25" velocity="100" />
  </joint>
  <joint name="palm_finger_2_joint" type="revolute">
    <parent link="palm" />
    <child link="finger_2_link_0" />
    <axis xyz="0 1 0" />
    <origin rpy="0 3.1416 -1.57" xyz="-0.0455 0.0214 -0.036" />
    <limit effort="100" lower="-0.25" upper="0.16" velocity="100" />
  </joint>
  <joint name="palm_finger_middle_joint" type="fixed">
    <parent link="palm" />
    <child link="finger_middle_link_0" />
    <axis xyz="0 0 1" />
    <origin rpy="0 0 1.57" xyz="0.0455 0.0214 0" />
  </joint>
  
</robot>