<robot name="">
	<link name="base_link">
		<inertial>
			<origin rpy="0.00000 -0.00000 0.00000" xyz="0.00000 0.00000 0.00000" />
			<mass value="1.00000" />
			<inertia ixx="0.03922" ixy="0" ixz="0" iyy="0.07568" iyz="0" izz="0.10640" />
		</inertial>
		<visual>
			<origin rpy="0.00000 -0.00000 0.00000" xyz="0.00000 0.00000 0.00000" />
			<geometry>
				<mesh filename="rlbotics/envs/models/robots/abb/irb4400/meshes/irb4400l_30_243/visual/base_link.stl" scale="1.00000 1.00000 1.00000" />
			</geometry>
			<material name="0">
				<color rgba="0.18824 0.19608 0.20392 1.00000" />
			</material>
		</visual>
		<collision>
			<origin rpy="0.00000 -0.00000 0.00000" xyz="0.00000 0.00000 0.00000" />
			<geometry>
				<mesh filename="rlbotics/envs/models/robots/abb/irb4400/meshes/irb4400l_30_243/collision/base_link.stl" scale="1.00000 1.00000 1.00000" />
			</geometry>
		</collision>
	</link>
	<link name="link_1">
		<inertial>
			<origin rpy="0.00000 -0.00000 0.00000" xyz="0.00000 0.00000 0.00000" />
			<mass value="1.00000" />
			<inertia ixx="0.12077" ixy="0" ixz="0" iyy="0.12169" iyz="0" izz="0.15600" />
		</inertial>
		<visual>
			<origin rpy="0.00000 -0.00000 0.00000" xyz="0.00000 0.00000 0.00000" />
			<geometry>
				<mesh filename="rlbotics/envs/models/robots/abb/irb4400/meshes/irb4400l_30_243/visual/link_1.stl" scale="1.00000 1.00000 1.00000" />
			</geometry>
			<material name="1">
				<color rgba="0.73725 0.34902 0.16078 1.00000" />
			</material>
		</visual>
		<collision>
			<origin rpy="0.00000 -0.00000 0.00000" xyz="0.00000 0.00000 0.00000" />
			<geometry>
				<mesh filename="rlbotics/envs/models/robots/abb/irb4400/meshes/irb4400l_30_243/collision/link_1.stl" scale="1.00000 1.00000 1.00000" />
			</geometry>
		</collision>
	</link>
	<link name="link_2">
		<inertial>
			<origin rpy="0.00000 -0.00000 0.00000" xyz="0.00000 0.00000 0.00000" />
			<mass value="1.00000" />
			<inertia ixx="0.11062" ixy="0" ixz="0" iyy="0.11480" iyz="0" izz="0.01469" />
		</inertial>
		<visual>
			<origin rpy="0.00000 -0.00000 0.00000" xyz="0.00000 0.00000 0.00000" />
			<geometry>
				<mesh filename="rlbotics/envs/models/robots/abb/irb4400/meshes/irb4400l_30_243/visual/link_2.stl" scale="1.00000 1.00000 1.00000" />
			</geometry>
			<material name="2">
				<color rgba="0.73725 0.34902 0.16078 1.00000" />
			</material>
		</visual>
		<collision>
			<origin rpy="0.00000 -0.00000 0.00000" xyz="0.00000 0.00000 0.00000" />
			<geometry>
				<mesh filename="rlbotics/envs/models/robots/abb/irb4400/meshes/irb4400l_30_243/collision/link_2.stl" scale="1.00000 1.00000 1.00000" />
			</geometry>
		</collision>
	</link>
	<link name="link_3">
		<inertial>
			<origin rpy="0.00000 -0.00000 0.00000" xyz="0.00000 0.00000 0.00000" />
			<mass value="1.00000" />
			<inertia ixx="0.02480" ixy="0" ixz="0" iyy="0.05612" iyz="0" izz="0.05646" />
		</inertial>
		<visual>
			<origin rpy="0.00000 -0.00000 0.00000" xyz="0.00000 0.00000 0.00000" />
			<geometry>
				<mesh filename="rlbotics/envs/models/robots/abb/irb4400/meshes/irb4400l_30_243/visual/link_3.stl" scale="1.00000 1.00000 1.00000" />
			</geometry>
			<material name="3">
				<color rgba="0.73725 0.34902 0.16078 1.00000" />
			</material>
		</visual>
		<collision>
			<origin rpy="0.00000 -0.00000 0.00000" xyz="0.00000 0.00000 0.00000" />
			<geometry>
				<mesh filename="rlbotics/envs/models/robots/abb/irb4400/meshes/irb4400l_30_243/collision/link_3.stl" scale="1.00000 1.00000 1.00000" />
			</geometry>
		</collision>
	</link>
	<link name="link_4">
		<inertial>
			<origin rpy="0.00000 -0.00000 0.00000" xyz="0.00000 0.00000 0.00000" />
			<mass value="1.00000" />
			<inertia ixx="0.01045" ixy="0" ixz="0" iyy="0.13699" iyz="0" izz="0.13770" />
		</inertial>
		<visual>
			<origin rpy="0.00000 -0.00000 0.00000" xyz="0.00000 0.00000 0.00000" />
			<geometry>
				<mesh filename="rlbotics/envs/models/robots/abb/irb4400/meshes/irb4400l_30_243/visual/link_4.stl" scale="1.00000 1.00000 1.00000" />
			</geometry>
			<material name="4">
				<color rgba="0.73725 0.34902 0.16078 1.00000" />
			</material>
		</visual>
		<collision>
			<origin rpy="0.00000 -0.00000 0.00000" xyz="0.00000 0.00000 0.00000" />
			<geometry>
				<mesh filename="rlbotics/envs/models/robots/abb/irb4400/meshes/irb4400l_30_243/collision/link_4.stl" scale="1.00000 1.00000 1.00000" />
			</geometry>
		</collision>
	</link>
	<link name="link_5">
		<inertial>
			<origin rpy="0.00000 -0.00000 0.00000" xyz="0.00000 0.00000 0.00000" />
			<mass value="1.00000" />
			<inertia ixx="0.00255" ixy="0" ixz="0" iyy="0.00530" iyz="0" izz="0.00362" />
		</inertial>
		<visual>
			<origin rpy="0.00000 -0.00000 0.00000" xyz="0.00000 0.00000 0.00000" />
			<geometry>
				<mesh filename="rlbotics/envs/models/robots/abb/irb4400/meshes/irb4400l_30_243/visual/link_5.stl" scale="1.00000 1.00000 1.00000" />
			</geometry>
			<material name="5">
				<color rgba="0.73725 0.34902 0.16078 1.00000" />
			</material>
		</visual>
		<collision>
			<origin rpy="0.00000 -0.00000 0.00000" xyz="0.00000 0.00000 0.00000" />
			<geometry>
				<mesh filename="rlbotics/envs/models/robots/abb/irb4400/meshes/irb4400l_30_243/collision/link_5.stl" scale="1.00000 1.00000 1.00000" />
			</geometry>
		</collision>
	</link>
	<link name="link_6">
		<inertial>
			<origin rpy="0.00000 -0.00000 0.00000" xyz="0.00000 0.00000 0.00000" />
			<mass value="1.00000" />
			<inertia ixx="0.00313" ixy="0" ixz="0" iyy="0.00524" iyz="0" izz="0.00536" />
		</inertial>
		<visual>
			<origin rpy="0.00000 -0.00000 0.00000" xyz="0.00000 0.00000 0.00000" />
			<geometry>
				<mesh filename="rlbotics/envs/models/robots/abb/irb4400/meshes/irb4400l_30_243/visual/link_6.stl" scale="1.00000 1.00000 1.00000" />
			</geometry>
			<material name="6">
				<color rgba="0.18824 0.19608 0.20392 1.00000" />
			</material>
		</visual>
		<collision>
			<origin rpy="0.00000 -0.00000 0.00000" xyz="0.00000 0.00000 0.00000" />
			<geometry>
				<mesh filename="rlbotics/envs/models/robots/abb/irb4400/meshes/irb4400l_30_243/collision/link_6.stl" scale="1.00000 1.00000 1.00000" />
			</geometry>
		</collision>
	</link>
	<link name="tool0">
		<inertial>
			<origin rpy="0.00000 -0.00000 0.00000" xyz="0.00000 0.00000 0.00000" />
			<mass value="1.00000" />
			<inertia ixx="0.00000" ixy="0" ixz="0" iyy="0.00000" iyz="0" izz="0.00000" />
		</inertial>
	</link>
	<link name="base">
		<inertial>
			<origin rpy="0.00000 -0.00000 0.00000" xyz="0.00000 0.00000 0.00000" />
			<mass value="1.00000" />
			<inertia ixx="0.00000" ixy="0" ixz="0" iyy="0.00000" iyz="0" izz="0.00000" />
		</inertial>
	</link>
	<link name="root">
		<inertial>
			<origin rpy="0.00000 -0.00000 0.00000" xyz="0.50570 -0.00054 0.18351" />
			<mass value="2.00000" />
			<inertia ixx="0.02909" ixy="0" ixz="0" iyy="0.13991" iyz="0" izz="0.11897" />
		</inertial>
		<visual>
			<origin rpy="0.00000 -0.00000 0.00000" xyz="0.39949 0.00000 0.14487" />
			<geometry>
				<mesh filename="rlbotics/envs/models/end_effectors/welding/spot_welding_gun/meshes/stl/RFC-22-G01 v2.stl" scale="0.00116 0.00116 0.00116" />
			</geometry>
			<material name="7">
				<color rgba="0.67059 0.67059 0.67059 1.00000" />
			</material>
		</visual>
		<collision>
			<origin rpy="0.00000 -0.00000 0.00000" xyz="0.39946 -0.00043 0.14496" />
			<geometry>
				<mesh filename="rlbotics/envs/models/end_effectors/welding/spot_welding_gun/meshes/stl/RFC-22-G01 v2.001.stl" scale="0.78991 0.78991 0.78991" />
			</geometry>
		</collision>
	</link>
	<link name="ee_joint_arm">
		<inertial>
			<origin rpy="0.00000 -0.00000 0.00000" xyz="0.00000 0.00000 0.00000" />
			<mass value="0.00100" />
			<inertia ixx="0.00000" ixy="0" ixz="0" iyy="0.00000" iyz="0" izz="0.00000" />
		</inertial>
	</link>
	<link name="nozzle_tip">
		<inertial>
			<origin rpy="0.00000 -0.00000 0.00000" xyz="0.00000 0.00000 0.00000" />
			<mass value="0.00100" />
			<inertia ixx="0.00000" ixy="0" ixz="0" iyy="0.00000" iyz="0" izz="0.00000" />
		</inertial>
	</link>
	<joint name="joint_1" type="revolute">
		<parent link="base_link" />
		<child link="link_1" />
		<dynamics damping="0.0" friction="0.0" />
		<origin rpy="0.00000 -0.00000 0.00000" xyz="0.00000 0.00000 0.00000" />
		<axis xyz="0.00000 0.00000 1.00000" />
	<limit effort="0.0" lower="-2.87979" upper="2.87979" velocity="2.618" /></joint>
	<joint name="joint_2" type="revolute">
		<parent link="link_1" />
		<child link="link_2" />
		<dynamics damping="0.0" friction="0.0" />
		<origin rpy="0.00000 -0.00000 0.00000" xyz="0.20000 0.00000 0.68000" />
		<axis xyz="0.00000 1.00000 0.00000" />
	<limit effort="0.0" lower="-1.2217" upper="1.658" velocity="2.0944" /></joint>
	<joint name="joint_3" type="revolute">
		<parent link="link_2" />
		<child link="link_3" />
		<dynamics damping="0.0" friction="0.0" />
		<origin rpy="0.00000 -0.00000 0.00000" xyz="0.00000 0.00000 0.89000" />
		<axis xyz="0.00000 1.00000 0.00000" />
	<limit effort="0.0" lower="-1.0472" upper="1.1345" velocity="2.0944" /></joint>
	<joint name="joint_4" type="revolute">
		<parent link="link_3" />
		<child link="link_4" />
		<dynamics damping="0.0" friction="0.0" />
		<origin rpy="0.00000 -0.00000 0.00000" xyz="1.38000 0.00000 0.15000" />
		<axis xyz="1.00000 0.00000 0.00000" />
	<limit effort="0.0" lower="-3.49" upper="3.49" velocity="3.927" /></joint>
	<joint name="joint_5" type="revolute">
		<parent link="link_4" />
		<child link="link_5" />
		<dynamics damping="0.0" friction="0.0" />
		<origin rpy="0.00000 -0.00000 0.00000" xyz="0.00000 0.00000 0.00000" />
		<axis xyz="0.00000 1.00000 0.00000" />
	<limit effort="0.0" lower="-2.0944" upper="2.0944" velocity="4.3633" /></joint>
	<joint name="joint_6" type="revolute">
		<parent link="link_5" />
		<child link="link_6" />
		<dynamics damping="0.0" friction="0.0" />
		<origin rpy="0.00000 -0.00000 0.00000" xyz="0.00000 0.00000 0.00000" />
		<axis xyz="1.00000 0.00000 0.00000" />
	<limit effort="0.0" lower="-6.9813" upper="6.9813" velocity="5.7596" /></joint>
	<joint name="joint_6-tool0" type="fixed">
		<parent link="link_6" />
		<child link="tool0" />
		<dynamics damping="1.0" friction="0.0001" />
		<origin rpy="0.00000 -0.00000 0.00000" xyz="0.14000 0.00000 0.00000" />
		<axis xyz="0.00000 0.00000 0.00000" />
	</joint>
	<joint name="base_link-base" type="fixed">
		<parent link="base_link" />
		<child link="base" />
		<dynamics damping="1.0" friction="0.0001" />
		<origin rpy="0.00000 -0.00000 0.00000" xyz="0.00000 0.00000 0.00000" />
		<axis xyz="0.00000 0.00000 0.00000" />
	</joint>
	<joint name="joint_dummy1" type="fixed">
		<parent link="link_6" />
		<child link="root" />
		<dynamics damping="1.0" friction="0.0001" />
		<origin rpy="0.00000 0.00000 0.00000" xyz="0.00000 0.00000 0.00000" />
		<axis xyz="0.00000 0.00000 1.00000" />
	</joint>
	<joint name="ee_joint_arm" type="fixed">
		<parent link="root" />
		<child link="ee_joint_arm" />
		<dynamics damping="1.0" friction="0.0001" />
		<origin rpy="0.00000 1.57080 -0.00000" xyz="-0.00372 -0.00266 0.00071" />
		<axis xyz="0.00000 0.00000 0.00000" />
	</joint>
	<joint name="nozzle_tip" type="fixed">
		<parent link="root" />
		<child link="nozzle_tip" />
		<dynamics damping="1.0" friction="0.0001" />
		<origin rpy="0.00000 1.57080 -0.00000" xyz="0.67936 0.00000 0.00043" />
		<axis xyz="0.00000 0.00000 0.00000" />
	</joint>
</robot>