<robot name="">
	<link name="base_link">
		<inertial>
			<origin rpy="0.00000 -0.00000 0.00000" xyz="0.00000 0.00000 0.00000" />
			<mass value="1.00000" />
			<inertia ixx="0.05644" ixy="0" ixz="0" iyy="0.09146" iyz="0" izz="0.13601" />
		</inertial>
		<visual>
			<origin rpy="0.00000 -0.00000 0.00000" xyz="0.00000 0.00000 0.00000" />
			<geometry>
				<mesh filename="rlbotics\envs\models\robots/abb/irb6600/meshes/irb6640/visual/base_link.stl" scale="1.00000 1.00000 1.00000" />
			</geometry>
			<material name="0">
				<color rgba="0.19608 0.18824 0.18824 1.00000" />
			</material>
		</visual>
		<collision>
			<origin rpy="0.00000 -0.00000 0.00000" xyz="0.00000 0.00000 0.00000" />
			<geometry>
				<mesh filename="rlbotics\envs\models\robots/abb/irb6600/meshes/irb6640/collision/base_link.stl" scale="1.00000 1.00000 1.00000" />
			</geometry>
		</collision>
	</link>
	<link name="link_1">
		<inertial>
			<origin rpy="0.00000 -0.00000 0.00000" xyz="0.00000 0.00000 0.00000" />
			<mass value="1.00000" />
			<inertia ixx="0.12168" ixy="0" ixz="0" iyy="0.14154" iyz="0" izz="0.14985" />
		</inertial>
		<visual>
			<origin rpy="0.00000 -0.00000 0.00000" xyz="0.00000 0.00000 0.00000" />
			<geometry>
				<mesh filename="rlbotics\envs\models\robots/abb/irb6600/meshes/irb6640/visual/link_1.stl" scale="1.00000 1.00000 1.00000" />
			</geometry>
			<material name="1">
				<color rgba="1.00000 0.43000 0.00000 1.00000" />
			</material>
		</visual>
		<collision>
			<origin rpy="0.00000 -0.00000 0.00000" xyz="0.00000 0.00000 0.00000" />
			<geometry>
				<mesh filename="rlbotics\envs\models\robots/abb/irb6600/meshes/irb6640/collision/link_1.stl" scale="1.00000 1.00000 1.00000" />
			</geometry>
		</collision>
	</link>
	<link name="link_2">
		<inertial>
			<origin rpy="0.00000 -0.00000 0.00000" xyz="0.00000 0.00000 0.00000" />
			<mass value="1.00000" />
			<inertia ixx="0.19273" ixy="0" ixz="0" iyy="0.19807" iyz="0" izz="0.04231" />
		</inertial>
		<visual>
			<origin rpy="0.00000 -0.00000 0.00000" xyz="0.00000 0.00000 0.00000" />
			<geometry>
				<mesh filename="rlbotics\envs\models\robots/abb/irb6600/meshes/irb6640/visual/link_2.stl" scale="1.00000 1.00000 1.00000" />
			</geometry>
			<material name="2">
				<color rgba="1.00000 0.43000 0.00000 1.00000" />
			</material>
		</visual>
		<collision>
			<origin rpy="0.00000 -0.00000 0.00000" xyz="0.00000 0.00000 0.00000" />
			<geometry>
				<mesh filename="rlbotics\envs\models\robots/abb/irb6600/meshes/irb6640/collision/link_2.stl" scale="1.00000 1.00000 1.00000" />
			</geometry>
		</collision>
	</link>
	<link name="link_3">
		<inertial>
			<origin rpy="0.00000 -0.00000 0.00000" xyz="0.00000 0.00000 0.00000" />
			<mass value="1.00000" />
			<inertia ixx="0.05700" ixy="0" ixz="0" iyy="0.05147" iyz="0" izz="0.05016" />
		</inertial>
		<visual>
			<origin rpy="0.00000 -0.00000 0.00000" xyz="0.00000 0.00000 0.00000" />
			<geometry>
				<mesh filename="rlbotics\envs\models\robots/abb/irb6600/meshes/irb6640/visual/link_3.stl" scale="1.00000 1.00000 1.00000" />
			</geometry>
			<material name="3">
				<color rgba="1.00000 0.43000 0.00000 1.00000" />
			</material>
		</visual>
		<collision>
			<origin rpy="0.00000 -0.00000 0.00000" xyz="0.00000 0.00000 0.00000" />
			<geometry>
				<mesh filename="rlbotics\envs\models\robots/abb/irb6600/meshes/irb6640/collision/link_3.stl" scale="1.00000 1.00000 1.00000" />
			</geometry>
		</collision>
	</link>
	<link name="link_4">
		<inertial>
			<origin rpy="0.00000 -0.00000 0.00000" xyz="0.00000 0.00000 0.00000" />
			<mass value="1.00000" />
			<inertia ixx="0.01678" ixy="0" ixz="0" iyy="0.27861" iyz="0" izz="0.28296" />
		</inertial>
		<visual>
			<origin rpy="0.00000 -0.00000 0.00000" xyz="0.00000 0.00000 0.00000" />
			<geometry>
				<mesh filename="rlbotics\envs\models\robots/abb/irb6600/meshes/irb6640/visual/link_4.stl" scale="1.00000 1.00000 1.00000" />
			</geometry>
			<material name="4">
				<color rgba="1.00000 0.43000 0.00000 1.00000" />
			</material>
		</visual>
		<collision>
			<origin rpy="0.00000 -0.00000 0.00000" xyz="0.00000 0.00000 0.00000" />
			<geometry>
				<mesh filename="rlbotics\envs\models\robots/abb/irb6600/meshes/irb6640/collision/link_4.stl" scale="1.00000 1.00000 1.00000" />
			</geometry>
		</collision>
	</link>
	<link name="link_5">
		<inertial>
			<origin rpy="0.00000 -0.00000 0.00000" xyz="0.00000 0.00000 0.00000" />
			<mass value="1.00000" />
			<inertia ixx="0.00698" ixy="0" ixz="0" iyy="0.01161" iyz="0" izz="0.01117" />
		</inertial>
		<visual>
			<origin rpy="0.00000 -0.00000 0.00000" xyz="0.00000 0.00000 0.00000" />
			<geometry>
				<mesh filename="rlbotics\envs\models\robots/abb/irb6600/meshes/irb6640/visual/link_5.stl" scale="1.00000 1.00000 1.00000" />
			</geometry>
			<material name="5">
				<color rgba="0.75294 0.75294 0.75294 1.00000" />
			</material>
		</visual>
		<collision>
			<origin rpy="0.00000 -0.00000 0.00000" xyz="0.00000 0.00000 0.00000" />
			<geometry>
				<mesh filename="rlbotics\envs\models\robots/abb/irb6600/meshes/irb6640/collision/link_5.stl" scale="1.00000 1.00000 1.00000" />
			</geometry>
		</collision>
	</link>
	<link name="link_6">
		<inertial>
			<origin rpy="0.00000 -0.00000 0.00000" xyz="0.00000 0.00000 0.00000" />
			<mass value="1.00000" />
			<inertia ixx="0.00719" ixy="0" ixz="0" iyy="0.00381" iyz="0" izz="0.00369" />
		</inertial>
		<visual>
			<origin rpy="0.00000 -0.00000 0.00000" xyz="0.00000 0.00000 0.00000" />
			<geometry>
				<mesh filename="rlbotics\envs\models\robots/abb/irb6600/meshes/irb6640/visual/link_6.stl" scale="1.00000 1.00000 1.00000" />
			</geometry>
			<material name="6">
				<color rgba="0.75294 0.75294 0.75294 1.00000" />
			</material>
		</visual>
		<collision>
			<origin rpy="0.00000 -0.00000 0.00000" xyz="0.00000 0.00000 0.00000" />
			<geometry>
				<mesh filename="rlbotics\envs\models\robots/abb/irb6600/meshes/irb6640/collision/link_6.stl" scale="1.00000 1.00000 1.00000" />
			</geometry>
		</collision>
	</link>
	<link name="tool0">
		<inertial>
			<origin rpy="0.00000 -0.00000 0.00000" xyz="0.00000 0.00000 0.00000" />
			<mass value="1.00000" />
			<inertia ixx="0.00000" ixy="0" ixz="0" iyy="0.00000" iyz="0" izz="0.00000" />
		</inertial>
	</link>
	<link name="link_cylinder">
		<inertial>
			<origin rpy="0.00000 -0.00000 0.00000" xyz="0.00000 0.00000 0.00000" />
			<mass value="1.00000" />
			<inertia ixx="0.03211" ixy="0" ixz="0" iyy="0.04966" iyz="0" izz="0.04355" />
		</inertial>
		<visual>
			<origin rpy="0.00000 -0.00000 0.00000" xyz="0.00000 0.00000 0.00000" />
			<geometry>
				<mesh filename="rlbotics\envs\models\robots/abb/irb6600/meshes/irb6640/visual/cylinder.stl" scale="1.00000 1.00000 1.00000" />
			</geometry>
			<material name="7">
				<color rgba="1.00000 0.43000 0.00000 1.00000" />
			</material>
		</visual>
		<collision>
			<origin rpy="0.00000 -0.00000 0.00000" xyz="0.00000 0.00000 0.00000" />
			<geometry>
				<mesh filename="rlbotics\envs\models\robots/abb/irb6600/meshes/irb6640/collision/cylinder.stl" scale="1.00000 1.00000 1.00000" />
			</geometry>
		</collision>
	</link>
	<link name="link_piston">
		<inertial>
			<origin rpy="0.00000 -0.00000 0.00000" xyz="0.00000 0.00000 0.00000" />
			<mass value="1.00000" />
			<inertia ixx="0.00136" ixy="0" ixz="0" iyy="0.03609" iyz="0" izz="0.03664" />
		</inertial>
		<visual>
			<origin rpy="0.00000 -0.00000 0.00000" xyz="0.00000 0.00000 0.00000" />
			<geometry>
				<mesh filename="rlbotics\envs\models\robots/abb/irb6600/meshes/irb6640/visual/piston.stl" scale="1.00000 1.00000 1.00000" />
			</geometry>
			<material name="8">
				<color rgba="0.75294 0.75294 0.75294 1.00000" />
			</material>
		</visual>
		<collision>
			<origin rpy="0.00000 -0.00000 0.00000" xyz="0.00000 0.00000 0.00000" />
			<geometry>
				<mesh filename="rlbotics\envs\models\robots/abb/irb6600/meshes/irb6640/collision/piston.stl" scale="1.00000 1.00000 1.00000" />
			</geometry>
		</collision>
	</link>
	<link name="base">
		<inertial>
			<origin rpy="0.00000 -0.00000 0.00000" xyz="0.00000 0.00000 0.00000" />
			<mass value="1.00000" />
			<inertia ixx="0.00000" ixy="0" ixz="0" iyy="0.00000" iyz="0" izz="0.00000" />
		</inertial>
	</link>
	<link name="root">
		<inertial>
			<origin rpy="0.00000 -0.00000 0.00000" xyz="0.50570 -0.00054 0.18351" />
			<mass value="2.00000" />
			<inertia ixx="0.02909" ixy="0" ixz="0" iyy="0.13991" iyz="0" izz="0.11897" />
		</inertial>
		<visual>
			<origin rpy="0.00000 -0.00000 0.00000" xyz="0.39949 0.00000 0.14487" />
			<geometry>
				<mesh filename="rlbotics\envs\models\end_effectors/welding/spot_welding_gun/meshes/stl/RFC-22-G01 v2.stl" scale="0.00116 0.00116 0.00116" />
			</geometry>
			<material name="9">
				<color rgba="0.67059 0.67059 0.67059 1.00000" />
			</material>
		</visual>
		<collision>
			<origin rpy="0.00000 -0.00000 0.00000" xyz="0.39946 -0.00043 0.14496" />
			<geometry>
				<mesh filename="rlbotics\envs\models\end_effectors/welding/spot_welding_gun/meshes/stl/RFC-22-G01 v2.001.stl" scale="0.78991 0.78991 0.78991" />
			</geometry>
		</collision>
	</link>
	<link name="ee_joint_arm">
		<inertial>
			<origin rpy="0.00000 -0.00000 0.00000" xyz="0.00000 0.00000 0.00000" />
			<mass value="0.00100" />
			<inertia ixx="0.00000" ixy="0" ixz="0" iyy="0.00000" iyz="0" izz="0.00000" />
		</inertial>
	</link>
	<link name="nozzle_tip">
		<inertial>
			<origin rpy="0.00000 -0.00000 0.00000" xyz="0.00000 0.00000 0.00000" />
			<mass value="0.00100" />
			<inertia ixx="0.00000" ixy="0" ixz="0" iyy="0.00000" iyz="0" izz="0.00000" />
		</inertial>
	</link>
	<joint name="joint_1" type="revolute">
		<parent link="base_link" />
		<child link="link_1" />
		<dynamics damping="0.0" friction="0.0" />
		<origin rpy="0.00000 -0.00000 0.00000" xyz="0.00000 0.00000 0.22700" />
		<axis xyz="0.00000 0.00000 1.00000" />
	<limit effort="0.0" lower="-2.967" upper="2.967" velocity="1.7453" /></joint>
	<joint name="joint_2" type="revolute">
		<parent link="link_1" />
		<child link="link_2" />
		<dynamics damping="0.0" friction="0.0" />
		<origin rpy="0.00000 -0.00000 0.00000" xyz="0.32200 0.03000 0.55100" />
		<axis xyz="0.00000 1.00000 0.00000" />
	<limit effort="0.0" lower="-1.134" upper="1.4855" velocity="1.5707" /></joint>
	<joint name="joint_3" type="revolute">
		<parent link="link_2" />
		<child link="link_3" />
		<dynamics damping="0.0" friction="0.0" />
		<origin rpy="0.00000 -0.00000 0.00000" xyz="0.00000 -0.20000 1.07000" />
		<axis xyz="0.00000 1.00000 0.00000" />
	<limit effort="0.0" lower="-3.142" upper="1.222" velocity="1.5707" /></joint>
	<joint name="joint_4" type="revolute">
		<parent link="link_3" />
		<child link="link_4" />
		<dynamics damping="0.0" friction="0.0" />
		<origin rpy="0.00000 -0.00000 0.00000" xyz="-0.27500 0.18100 0.20000" />
		<axis xyz="1.00000 0.00000 0.00000" />
	<limit effort="0.0" lower="-5.236" upper="5.236" velocity="2.9671" /></joint>
	<joint name="joint_5" type="revolute">
		<parent link="link_4" />
		<child link="link_5" />
		<dynamics damping="0.0" friction="0.0" />
		<origin rpy="0.00000 -0.00000 0.00000" xyz="1.67000 0.00000 0.00000" />
		<axis xyz="0.00000 1.00000 0.00000" />
	<limit effort="0.0" lower="-2.094" upper="2.094" velocity="2.4435" /></joint>
	<joint name="joint_6" type="revolute">
		<parent link="link_5" />
		<child link="link_6" />
		<dynamics damping="0.0" friction="0.0" />
		<origin rpy="0.00000 -0.00000 0.00000" xyz="0.15300 0.00000 0.00000" />
		<axis xyz="1.00000 0.00000 0.00000" />
	<limit effort="0.0" lower="-6.283" upper="6.283" velocity="3.3161" /></joint>
	<joint name="joint_6-tool0" type="fixed">
		<parent link="link_6" />
		<child link="tool0" />
		<dynamics damping="1.0" friction="0.0001" />
		<origin rpy="0.00000 1.57080 -0.00000" xyz="0.05500 0.00000 0.00000" />
		<axis xyz="0.00000 0.00000 0.00000" />
	</joint>
	<joint name="joint_cylinder" type="fixed">
		<parent link="link_1" />
		<child link="link_cylinder" />
		<dynamics damping="1.0" friction="0.0001" />
		<origin rpy="0.00000 -0.17000 0.00000" xyz="-0.36500 -0.18950 0.40500" />
		<axis xyz="0.00000 0.00000 0.00000" />
	</joint>
	<joint name="joint_piston" type="fixed">
		<parent link="link_cylinder" />
		<child link="link_piston" />
		<dynamics damping="1.0" friction="0.0001" />
		<origin rpy="0.00000 -0.00000 0.00000" xyz="0.47500 0.00000 0.00000" />
		<axis xyz="0.00000 0.00000 0.00000" />
	</joint>
	<joint name="base_link-base" type="fixed">
		<parent link="base_link" />
		<child link="base" />
		<dynamics damping="1.0" friction="0.0001" />
		<origin rpy="0.00000 -0.00000 0.00000" xyz="0.00000 0.00000 0.00000" />
		<axis xyz="0.00000 0.00000 0.00000" />
	</joint>
	<joint name="joint_dummy1" type="fixed">
		<parent link="link_6" />
		<child link="root" />
		<dynamics damping="1.0" friction="0.0001" />
		<origin rpy="0.00000 0.00000 0.00000" xyz="0.00000 0.00000 0.00000" />
		<axis xyz="0.00000 0.00000 1.00000" />
	</joint>
	<joint name="ee_joint_arm" type="fixed">
		<parent link="root" />
		<child link="ee_joint_arm" />
		<dynamics damping="1.0" friction="0.0001" />
		<origin rpy="0.00000 1.57080 -0.00000" xyz="-0.00372 -0.00266 0.00071" />
		<axis xyz="0.00000 0.00000 0.00000" />
	</joint>
	<joint name="nozzle_tip" type="fixed">
		<parent link="root" />
		<child link="nozzle_tip" />
		<dynamics damping="1.0" friction="0.0001" />
		<origin rpy="0.00000 1.57080 -0.00000" xyz="0.67936 0.00000 0.00043" />
		<axis xyz="0.00000 0.00000 0.00000" />
	</joint>
</robot>