<robot name="">
	<link name="base_link">
		<inertial>
			<origin rpy="0.00000 -0.00000 0.00000" xyz="-0.02780 0.00039 0.14035" />
			<mass value="1572.90000" />
			<inertia ixx="147.38224" ixy="0" ixz="0" iyy="202.17262" iyz="0" izz="319.78450" />
		</inertial>
		<visual>
			<origin rpy="-1.57080 0.00000 0.00000" xyz="0.00000 0.00000 0.00000" />
			<geometry>
				<mesh filename="rlbotics/envs/models/robots/kuka/kr210/meshes/kr210l150/visual/base_link.stl" scale="1.00000 1.00000 1.00000" />
			</geometry>
			<material name="0">
				<color rgba="0.05490 0.14510 0.20000 1.00000" />
			</material>
		</visual>
		<collision>
			<origin rpy="-1.57080 0.00000 0.00000" xyz="0.00000 0.00000 0.00000" />
			<geometry>
				<mesh filename="rlbotics/envs/models/robots/kuka/kr210/meshes/kr210l150/collision/base_link.stl" scale="1.00000 1.00000 1.00000" />
			</geometry>
		</collision>
	</link>
	<link name="link_1">
		<inertial>
			<origin rpy="0.00000 -0.00000 0.00000" xyz="-0.03681 -0.02470 0.56577" />
			<mass value="1385.50000" />
			<inertia ixx="150.64281" ixy="0" ixz="0" iyy="203.49709" iyz="0" izz="250.48282" />
		</inertial>
		<visual>
			<origin rpy="0.00000 -0.00000 0.00000" xyz="0.00000 0.00000 0.00000" />
			<geometry>
				<mesh filename="rlbotics/envs/models/robots/kuka/kr210/meshes/kr210l150/visual/link_1.stl" scale="1.00000 1.00000 1.00000" />
			</geometry>
			<material name="1">
				<color rgba="0.94902 0.36078 0.09804 1.00000" />
			</material>
		</visual>
		<collision>
			<origin rpy="0.00000 -0.00000 0.00000" xyz="0.00000 0.00000 0.00000" />
			<geometry>
				<mesh filename="rlbotics/envs/models/robots/kuka/kr210/meshes/kr210l150/collision/link_1.stl" scale="1.00000 1.00000 1.00000" />
			</geometry>
		</collision>
	</link>
	<link name="link_2">
		<inertial>
			<origin rpy="0.00000 -0.00000 0.00000" xyz="0.01692 -0.19196 0.44751" />
			<mass value="958.62000" />
			<inertia ixx="242.63225" ixy="0" ixz="0" iyy="241.46543" iyz="0" izz="38.45678" />
		</inertial>
		<visual>
			<origin rpy="-1.57080 0.00000 0.00000" xyz="0.00000 0.00000 0.00000" />
			<geometry>
				<mesh filename="rlbotics/envs/models/robots/kuka/kr210/meshes/kr210l150/visual/link_2.stl" scale="1.00000 1.00000 1.00000" />
			</geometry>
			<material name="2">
				<color rgba="0.94902 0.36078 0.09804 1.00000" />
			</material>
		</visual>
		<collision>
			<origin rpy="0.00000 -0.00000 0.00000" xyz="0.00000 0.00000 0.00000" />
			<geometry>
				<mesh filename="rlbotics/envs/models/robots/kuka/kr210/meshes/kr210l150/collision/link_2.stl" scale="1.00000 1.00000 1.00000" />
			</geometry>
		</collision>
	</link>
	<link name="link_3">
		<inertial>
			<origin rpy="0.00000 -0.00000 0.00000" xyz="0.18842 0.18344 -0.04280" />
			<mass value="710.03000" />
			<inertia ixx="31.03103" ixy="0" ixz="0" iyy="128.15244" iyz="0" izz="124.72848" />
		</inertial>
		<visual>
			<origin rpy="-1.57080 0.00000 0.00000" xyz="0.00000 0.00000 0.00000" />
			<geometry>
				<mesh filename="rlbotics/envs/models/robots/kuka/kr210/meshes/kr210l150/visual/link_3.stl" scale="1.00000 1.00000 1.00000" />
			</geometry>
			<material name="3">
				<color rgba="0.94902 0.36078 0.09804 1.00000" />
			</material>
		</visual>
		<collision>
			<origin rpy="0.00000 -0.00000 0.00000" xyz="0.00000 0.00000 0.00000" />
			<geometry>
				<mesh filename="rlbotics/envs/models/robots/kuka/kr210/meshes/kr210l150/collision/link_3.stl" scale="1.00000 1.00000 1.00000" />
			</geometry>
		</collision>
	</link>
	<link name="link_4">
		<inertial>
			<origin rpy="0.00000 -0.00000 0.00000" xyz="0.27146 -0.00733 0.00005" />
			<mass value="173.73000" />
			<inertia ixx="2.59544" ixy="0" ixz="0" iyy="7.06362" iyz="0" izz="7.87822" />
		</inertial>
		<visual>
			<origin rpy="-1.57080 0.00000 0.00000" xyz="0.00000 0.00000 0.00000" />
			<geometry>
				<mesh filename="rlbotics/envs/models/robots/kuka/kr210/meshes/kr210l150/visual/link_4.stl" scale="1.00000 1.00000 1.00000" />
			</geometry>
			<material name="4">
				<color rgba="0.94902 0.36078 0.09804 1.00000" />
			</material>
		</visual>
		<collision>
			<origin rpy="0.00000 -0.00000 0.00000" xyz="0.00000 0.00000 0.00000" />
			<geometry>
				<mesh filename="rlbotics/envs/models/robots/kuka/kr210/meshes/kr210l150/collision/link_4.stl" scale="1.00000 1.00000 1.00000" />
			</geometry>
		</collision>
	</link>
	<link name="link_5">
		<inertial>
			<origin rpy="0.00000 -0.00000 0.00000" xyz="0.04379 0.02598 0.00000" />
			<mass value="72.17000" />
			<inertia ixx="0.72730" ixy="0" ixz="0" iyy="0.97404" iyz="0" izz="0.97344" />
		</inertial>
		<visual>
			<origin rpy="-1.57080 0.00000 0.00000" xyz="0.00000 0.00000 0.00000" />
			<geometry>
				<mesh filename="rlbotics/envs/models/robots/kuka/kr210/meshes/kr210l150/visual/link_5.stl" scale="1.00000 1.00000 1.00000" />
			</geometry>
			<material name="5">
				<color rgba="0.94902 0.36078 0.09804 1.00000" />
			</material>
		</visual>
		<collision>
			<origin rpy="0.00000 -0.00000 0.00000" xyz="0.00000 0.00000 0.00000" />
			<geometry>
				<mesh filename="rlbotics/envs/models/robots/kuka/kr210/meshes/kr210l150/collision/link_5.stl" scale="1.00000 1.00000 1.00000" />
			</geometry>
		</collision>
	</link>
	<link name="link_6">
		<inertial>
			<origin rpy="0.00000 -0.00000 0.00000" xyz="-0.01796 -0.00002 0.00015" />
			<mass value="6.31540" />
			<inertia ixx="0.04370" ixy="0" ixz="0" iyy="0.02283" iyz="0" izz="0.02286" />
		</inertial>
		<visual>
			<origin rpy="0.00000 -0.00000 0.00000" xyz="0.00000 0.00000 0.00000" />
			<geometry>
				<mesh filename="rlbotics/envs/models/robots/kuka/kr210/meshes/kr210l150/visual/link_6.stl" scale="1.00000 1.00000 1.00000" />
			</geometry>
			<material name="6">
				<color rgba="0.75294 0.75294 0.75294 1.00000" />
			</material>
		</visual>
		<collision>
			<origin rpy="0.00000 -0.00000 0.00000" xyz="0.00000 0.00000 0.00000" />
			<geometry>
				<mesh filename="rlbotics/envs/models/robots/kuka/kr210/meshes/kr210l150/collision/link_6.stl" scale="1.00000 1.00000 1.00000" />
			</geometry>
		</collision>
	</link>
	<link name="tool0">
		<inertial>
			<origin rpy="0.00000 -0.00000 0.00000" xyz="0.00000 0.00000 0.00000" />
			<mass value="1.00000" />
			<inertia ixx="0.00000" ixy="0" ixz="0" iyy="0.00000" iyz="0" izz="0.00000" />
		</inertial>
	</link>
	<link name="Link1">
		<inertial>
			<origin rpy="0.00000 -0.00000 0.00000" xyz="0.00000 0.00000 0.00000" />
			<mass value="1.00000" />
			<inertia ixx="0.00000" ixy="0" ixz="0" iyy="0.00000" iyz="0" izz="0.00000" />
		</inertial>
	</link>
	<link name="robotiq_arg2f_base_link">
		<inertial>
			<origin rpy="0.00000 -0.00000 0.00000" xyz="0.00000 -0.00000 0.03145" />
			<mass value="0.22652" />
			<inertia ixx="0.00034" ixy="0" ixz="0" iyy="0.00031" iyz="0" izz="0.00028" />
		</inertial>
		<visual>
			<origin rpy="0.00000 -0.00000 0.00000" xyz="0.00000 0.00000 0.00000" />
			<geometry>
				<mesh filename="rlbotics/envs/models/end_effectors/robotiq/robotiq_2f_85/meshes/visual/robotiq_arg2f_85_base_link.dae" scale="0.00100 0.00100 0.00100" />
			</geometry>
			<material name="7">
				<color rgba="0.10000 0.10000 0.10000 1.00000" />
			</material>
		</visual>
		<collision>
			<origin rpy="0.00000 -0.00000 0.00000" xyz="0.00000 0.00000 0.00000" />
			<geometry>
				<mesh filename="rlbotics/envs/models/end_effectors/robotiq/robotiq_2f_85/meshes/collision/robotiq_arg2f_base_link.stl" scale="1.00000 1.00000 1.00000" />
			</geometry>
		</collision>
	</link>
	<link name="left_outer_knuckle">
		<inertial>
			<origin rpy="0.00000 -0.00000 0.00000" xyz="0.00000 0.00000 0.00000" />
			<mass value="1.00000" />
			<inertia ixx="0.00030" ixy="0" ixz="0" iyy="0.00014" iyz="0" izz="0.00030" />
		</inertial>
		<visual>
			<origin rpy="0.00000 -0.00000 0.00000" xyz="0.00000 0.00000 0.00000" />
			<geometry>
				<mesh filename="rlbotics/envs/models/end_effectors/robotiq/robotiq_2f_85/meshes/visual/robotiq_arg2f_85_outer_knuckle.dae" scale="0.00100 0.00100 0.00100" />
			</geometry>
			<material name="8">
				<color rgba="0.79216 0.81961 0.93333 1.00000" />
			</material>
		</visual>
		<collision>
			<origin rpy="0.00000 -0.00000 0.00000" xyz="0.00000 0.00000 0.00000" />
			<geometry>
				<mesh filename="rlbotics/envs/models/end_effectors/robotiq/robotiq_2f_85/meshes/collision/robotiq_arg2f_85_outer_knuckle.dae" scale="0.00100 0.00100 0.00100" />
			</geometry>
		</collision>
	</link>
	<link name="left_outer_finger">
		<inertial>
			<origin rpy="0.00000 -0.00000 0.00000" xyz="0.00000 0.00000 0.00000" />
			<mass value="1.00000" />
			<inertia ixx="0.00040" ixy="0" ixz="0" iyy="0.00044" iyz="0" izz="0.00014" />
		</inertial>
		<visual>
			<origin rpy="0.00000 -0.00000 0.00000" xyz="0.00000 0.00000 0.00000" />
			<geometry>
				<mesh filename="rlbotics/envs/models/end_effectors/robotiq/robotiq_2f_85/meshes/visual/robotiq_arg2f_85_outer_finger.dae" scale="0.00100 0.00100 0.00100" />
			</geometry>
			<material name="9">
				<color rgba="0.10000 0.10000 0.10000 1.00000" />
			</material>
		</visual>
		<collision>
			<origin rpy="0.00000 -0.00000 0.00000" xyz="0.00000 0.00000 0.00000" />
			<geometry>
				<mesh filename="rlbotics/envs/models/end_effectors/robotiq/robotiq_2f_85/meshes/collision/robotiq_arg2f_85_outer_finger.dae" scale="0.00100 0.00100 0.00100" />
			</geometry>
		</collision>
	</link>
	<link name="left_inner_finger">
		<inertial>
			<origin rpy="0.00000 -0.00000 0.00000" xyz="0.00000 0.00000 0.00000" />
			<mass value="1.00000" />
			<inertia ixx="0.00037" ixy="0" ixz="0" iyy="0.00030" iyz="0" izz="0.00014" />
		</inertial>
		<visual>
			<origin rpy="0.00000 -0.00000 0.00000" xyz="0.00000 0.00000 0.00000" />
			<geometry>
				<mesh filename="rlbotics/envs/models/end_effectors/robotiq/robotiq_2f_85/meshes/visual/robotiq_arg2f_85_inner_finger.dae" scale="0.00100 0.00100 0.00100" />
			</geometry>
			<material name="10">
				<color rgba="0.10000 0.10000 0.10000 1.00000" />
			</material>
		</visual>
		<collision>
			<origin rpy="0.00000 -0.00000 0.00000" xyz="0.00000 0.00000 0.00000" />
			<geometry>
				<mesh filename="rlbotics/envs/models/end_effectors/robotiq/robotiq_2f_85/meshes/collision/robotiq_arg2f_85_inner_finger.dae" scale="0.00100 0.00100 0.00100" />
			</geometry>
		</collision>
	</link>
	<link name="left_inner_finger_pad">
		<inertial>
			<origin rpy="0.00000 -0.00000 0.00000" xyz="0.00000 0.00000 0.00000" />
			<mass value="1.00000" />
			<inertia ixx="0.00012" ixy="0" ixz="0" iyy="0.00016" iyz="0" izz="0.00004" />
		</inertial>
		<visual>
			<origin rpy="0.00000 -0.00000 0.00000" xyz="0.00000 0.00000 0.00000" />
			<geometry>
				<box size="0.02200 0.00635 0.03750" />
			</geometry>
			<material name="11">
				<color rgba="0.90000 0.90000 0.90000 1.00000" />
			</material>
		</visual>
		<collision>
			<origin rpy="0.00000 -0.00000 0.00000" xyz="0.00000 0.00000 0.00000" />
			<geometry>
				<box size="0.02200 0.00635 0.03750" />
			</geometry>
		</collision>
	</link>
	<link name="left_inner_knuckle">
		<inertial>
			<origin rpy="0.00000 -0.00000 0.00000" xyz="0.00000 0.00000 0.00000" />
			<mass value="1.00000" />
			<inertia ixx="0.00057" ixy="0" ixz="0" iyy="0.00048" iyz="0" izz="0.00042" />
		</inertial>
		<visual>
			<origin rpy="0.00000 -0.00000 0.00000" xyz="0.00000 0.00000 0.00000" />
			<geometry>
				<mesh filename="rlbotics/envs/models/end_effectors/robotiq/robotiq_2f_85/meshes/visual/robotiq_arg2f_85_inner_knuckle.dae" scale="0.00100 0.00100 0.00100" />
			</geometry>
			<material name="12">
				<color rgba="0.10000 0.10000 0.10000 1.00000" />
			</material>
		</visual>
		<collision>
			<origin rpy="0.00000 -0.00000 0.00000" xyz="0.00000 0.00000 0.00000" />
			<geometry>
				<mesh filename="rlbotics/envs/models/end_effectors/robotiq/robotiq_2f_85/meshes/collision/robotiq_arg2f_85_inner_knuckle.dae" scale="0.00100 0.00100 0.00100" />
			</geometry>
		</collision>
	</link>
	<link name="right_outer_knuckle">
		<inertial>
			<origin rpy="0.00000 -0.00000 0.00000" xyz="0.00000 0.00000 0.00000" />
			<mass value="1.00000" />
			<inertia ixx="0.00030" ixy="0" ixz="0" iyy="0.00014" iyz="0" izz="0.00030" />
		</inertial>
		<visual>
			<origin rpy="0.00000 -0.00000 0.00000" xyz="0.00000 0.00000 0.00000" />
			<geometry>
				<mesh filename="rlbotics/envs/models/end_effectors/robotiq/robotiq_2f_85/meshes/visual/robotiq_arg2f_85_outer_knuckle.dae" scale="0.00100 0.00100 0.00100" />
			</geometry>
			<material name="13">
				<color rgba="0.79216 0.81961 0.93333 1.00000" />
			</material>
		</visual>
		<collision>
			<origin rpy="0.00000 -0.00000 0.00000" xyz="0.00000 0.00000 0.00000" />
			<geometry>
				<mesh filename="rlbotics/envs/models/end_effectors/robotiq/robotiq_2f_85/meshes/collision/robotiq_arg2f_85_outer_knuckle.dae" scale="0.00100 0.00100 0.00100" />
			</geometry>
		</collision>
	</link>
	<link name="right_outer_finger">
		<inertial>
			<origin rpy="0.00000 -0.00000 0.00000" xyz="0.00000 0.00000 0.00000" />
			<mass value="1.00000" />
			<inertia ixx="0.00040" ixy="0" ixz="0" iyy="0.00044" iyz="0" izz="0.00014" />
		</inertial>
		<visual>
			<origin rpy="0.00000 -0.00000 0.00000" xyz="0.00000 0.00000 0.00000" />
			<geometry>
				<mesh filename="rlbotics/envs/models/end_effectors/robotiq/robotiq_2f_85/meshes/visual/robotiq_arg2f_85_outer_finger.dae" scale="0.00100 0.00100 0.00100" />
			</geometry>
			<material name="14">
				<color rgba="0.10000 0.10000 0.10000 1.00000" />
			</material>
		</visual>
		<collision>
			<origin rpy="0.00000 -0.00000 0.00000" xyz="0.00000 0.00000 0.00000" />
			<geometry>
				<mesh filename="rlbotics/envs/models/end_effectors/robotiq/robotiq_2f_85/meshes/collision/robotiq_arg2f_85_outer_finger.dae" scale="0.00100 0.00100 0.00100" />
			</geometry>
		</collision>
	</link>
	<link name="right_inner_finger">
		<inertial>
			<origin rpy="0.00000 -0.00000 0.00000" xyz="0.00000 0.00000 0.00000" />
			<mass value="1.00000" />
			<inertia ixx="0.00037" ixy="0" ixz="0" iyy="0.00030" iyz="0" izz="0.00014" />
		</inertial>
		<visual>
			<origin rpy="0.00000 -0.00000 0.00000" xyz="0.00000 0.00000 0.00000" />
			<geometry>
				<mesh filename="rlbotics/envs/models/end_effectors/robotiq/robotiq_2f_85/meshes/visual/robotiq_arg2f_85_inner_finger.dae" scale="0.00100 0.00100 0.00100" />
			</geometry>
			<material name="15">
				<color rgba="0.10000 0.10000 0.10000 1.00000" />
			</material>
		</visual>
		<collision>
			<origin rpy="0.00000 -0.00000 0.00000" xyz="0.00000 0.00000 0.00000" />
			<geometry>
				<mesh filename="rlbotics/envs/models/end_effectors/robotiq/robotiq_2f_85/meshes/collision/robotiq_arg2f_85_inner_finger.dae" scale="0.00100 0.00100 0.00100" />
			</geometry>
		</collision>
	</link>
	<link name="right_inner_finger_pad">
		<inertial>
			<origin rpy="0.00000 -0.00000 0.00000" xyz="0.00000 0.00000 0.00000" />
			<mass value="1.00000" />
			<inertia ixx="0.00012" ixy="0" ixz="0" iyy="0.00016" iyz="0" izz="0.00004" />
		</inertial>
		<visual>
			<origin rpy="0.00000 -0.00000 0.00000" xyz="0.00000 0.00000 0.00000" />
			<geometry>
				<box size="0.02200 0.00635 0.03750" />
			</geometry>
			<material name="16">
				<color rgba="0.90000 0.90000 0.90000 1.00000" />
			</material>
		</visual>
		<collision>
			<origin rpy="0.00000 -0.00000 0.00000" xyz="0.00000 0.00000 0.00000" />
			<geometry>
				<box size="0.02200 0.00635 0.03750" />
			</geometry>
		</collision>
	</link>
	<link name="right_inner_knuckle">
		<inertial>
			<origin rpy="0.00000 -0.00000 0.00000" xyz="0.00000 0.00000 0.00000" />
			<mass value="1.00000" />
			<inertia ixx="0.00057" ixy="0" ixz="0" iyy="0.00048" iyz="0" izz="0.00042" />
		</inertial>
		<visual>
			<origin rpy="0.00000 -0.00000 0.00000" xyz="0.00000 0.00000 0.00000" />
			<geometry>
				<mesh filename="rlbotics/envs/models/end_effectors/robotiq/robotiq_2f_85/meshes/visual/robotiq_arg2f_85_inner_knuckle.dae" scale="0.00100 0.00100 0.00100" />
			</geometry>
			<material name="17">
				<color rgba="0.10000 0.10000 0.10000 1.00000" />
			</material>
		</visual>
		<collision>
			<origin rpy="0.00000 -0.00000 0.00000" xyz="0.00000 0.00000 0.00000" />
			<geometry>
				<mesh filename="rlbotics/envs/models/end_effectors/robotiq/robotiq_2f_85/meshes/collision/robotiq_arg2f_85_inner_knuckle.dae" scale="0.00100 0.00100 0.00100" />
			</geometry>
		</collision>
	</link>
	<joint name="joint_a1" type="revolute">
		<parent link="base_link" />
		<child link="link_1" />
		<dynamics damping="0.0" friction="0.0" />
		<origin rpy="0.00000 -0.00000 0.00000" xyz="-0.00262 0.00098 0.33099" />
		<axis xyz="0.00000 0.00000 1.00000" />
	<limit effort="0.0" lower="-3.2288591161895095" upper="3.2288591161895095" velocity="2.1467549799530254" /></joint>
	<joint name="joint_a2" type="revolute">
		<parent link="link_1" />
		<child link="link_2" />
		<dynamics damping="0.0" friction="0.0" />
		<origin rpy="0.00000 -0.00000 0.00000" xyz="0.35277 -0.03748 0.41920" />
		<axis xyz="0.00000 1.00000 0.00000" />
	<limit effort="0.0" lower="-0.7853981633974483" upper="1.4835298641951802" velocity="2.007128639793479" /></joint>
	<joint name="joint_a3" type="revolute">
		<parent link="link_2" />
		<child link="link_3" />
		<dynamics damping="0.0" friction="0.0" />
		<origin rpy="0.00000 -0.00000 0.00000" xyz="-0.00010 -0.14750 1.24990" />
		<axis xyz="0.00000 1.00000 0.00000" />
	<limit effort="0.0" lower="-3.6651914291880923" upper="1.1344640137963142" velocity="1.9547687622336491" /></joint>
	<joint name="joint_a4" type="revolute">
		<parent link="link_3" />
		<child link="link_4" />
		<dynamics damping="0.0" friction="0.0" />
		<origin rpy="0.00000 -0.00000 0.00000" xyz="0.95795 0.18400 -0.05506" />
		<axis xyz="1.00000 0.00000 0.00000" />
	<limit effort="0.0" lower="-6.1086523819801535" upper="6.1086523819801535" velocity="3.12413936106985" /></joint>
	<joint name="joint_a5" type="revolute">
		<parent link="link_4" />
		<child link="link_5" />
		<dynamics damping="0.0" friction="0.0" />
		<origin rpy="0.00000 -0.00000 0.00000" xyz="0.54200 0.00000 0.00000" />
		<axis xyz="0.00000 1.00000 0.00000" />
	<limit effort="0.0" lower="-2.181661564992912" upper="2.181661564992912" velocity="3.001966313430247" /></joint>
	<joint name="joint_a6" type="revolute">
		<parent link="link_5" />
		<child link="link_6" />
		<dynamics damping="0.0" friction="0.0" />
		<origin rpy="0.00000 -0.00000 0.00000" xyz="0.19250 0.00000 0.00000" />
		<axis xyz="1.00000 0.00000 0.00000" />
	<limit effort="0.0" lower="-6.1086523819801535" upper="6.1086523819801535" velocity="3.822271061867582" /></joint>
	<joint name="link_6-tool0" type="fixed">
		<parent link="link_6" />
		<child link="tool0" />
		<dynamics damping="1.0" friction="0.0001" />
		<origin rpy="0.00000 -0.00000 0.00000" xyz="0.03750 0.00000 -0.00024" />
		<axis xyz="0.00000 0.00000 0.00000" />
	</joint>
	<joint name="Link1-link_1" type="fixed">
		<parent link="link_1" />
		<child link="Link1" />
		<dynamics damping="1.0" friction="0.0001" />
		<origin rpy="0.00000 -0.00000 0.00000" xyz="0.00000 0.00000 0.00000" />
		<axis xyz="0.00000 0.00000 0.00000" />
	</joint>
	<joint name="joint_dummy1" type="fixed">
		<parent link="link_6" />
		<child link="robotiq_arg2f_base_link" />
		<dynamics damping="1.0" friction="0.0001" />
		<origin rpy="0.00000 1.57080 0.00000" xyz="0.00000 0.00000 0.00000" />
		<axis xyz="0.00000 0.00000 1.00000" />
	</joint>
	<joint name="finger_joint" type="revolute">
		<parent link="robotiq_arg2f_base_link" />
		<child link="left_outer_knuckle" />
		<dynamics damping="0.0" friction="0.0" />
		<origin rpy="0.00000 -0.00000 3.14159" xyz="0.00000 -0.03060 0.05490" />
		<axis xyz="1.00000 0.00000 0.00000" />
	<limit effort="1000.0" lower="0.0" upper="0.8" velocity="2.0" /></joint>
	<joint name="left_outer_finger_joint" type="fixed">
		<parent link="left_outer_knuckle" />
		<child link="left_outer_finger" />
		<dynamics damping="1.0" friction="0.0001" />
		<origin rpy="0.00000 -0.00000 0.00000" xyz="0.00000 0.03150 -0.00410" />
		<axis xyz="0.00000 0.00000 0.00000" />
	</joint>
	<joint name="left_inner_finger_joint" type="revolute">
		<parent link="left_outer_finger" />
		<child link="left_inner_finger" />
		<dynamics damping="0.0" friction="0.0" />
		<origin rpy="0.00000 -0.00000 0.00000" xyz="0.00000 0.00610 0.04710" />
		<axis xyz="1.00000 0.00000 0.00000" />
	<limit effort="1000.0" lower="0.0" upper="0.8757" velocity="2.0" /></joint>
	<joint name="left_inner_finger_pad_joint" type="fixed">
		<parent link="left_inner_finger" />
		<child link="left_inner_finger_pad" />
		<dynamics damping="1.0" friction="0.0001" />
		<origin rpy="0.00000 -0.00000 0.00000" xyz="0.00000 -0.02202 0.03242" />
		<axis xyz="0.00000 0.00000 0.00000" />
	</joint>
	<joint name="left_inner_knuckle_joint" type="revolute">
		<parent link="robotiq_arg2f_base_link" />
		<child link="left_inner_knuckle" />
		<dynamics damping="0.0" friction="0.0" />
		<origin rpy="0.00000 -0.00000 3.14159" xyz="0.00000 -0.01270 0.06142" />
		<axis xyz="1.00000 0.00000 0.00000" />
	<limit effort="1000.0" lower="0.0" upper="0.8757" velocity="2.0" /></joint>
	<joint name="right_outer_knuckle_joint" type="revolute">
		<parent link="robotiq_arg2f_base_link" />
		<child link="right_outer_knuckle" />
		<dynamics damping="0.0" friction="0.0" />
		<origin rpy="0.00000 -0.00000 0.00000" xyz="0.00000 0.03060 0.05490" />
		<axis xyz="1.00000 0.00000 0.00000" />
	<limit effort="1000.0" lower="0.0" upper="0.81" velocity="2.0" /></joint>
	<joint name="right_outer_finger_joint" type="fixed">
		<parent link="right_outer_knuckle" />
		<child link="right_outer_finger" />
		<dynamics damping="1.0" friction="0.0001" />
		<origin rpy="0.00000 -0.00000 0.00000" xyz="0.00000 0.03150 -0.00410" />
		<axis xyz="0.00000 0.00000 0.00000" />
	</joint>
	<joint name="right_inner_finger_joint" type="revolute">
		<parent link="right_outer_finger" />
		<child link="right_inner_finger" />
		<dynamics damping="0.0" friction="0.0" />
		<origin rpy="0.00000 -0.00000 0.00000" xyz="0.00000 0.00610 0.04710" />
		<axis xyz="1.00000 0.00000 0.00000" />
	<limit effort="1000.0" lower="0.0" upper="0.8757" velocity="2.0" /></joint>
	<joint name="right_inner_finger_pad_joint" type="fixed">
		<parent link="right_inner_finger" />
		<child link="right_inner_finger_pad" />
		<dynamics damping="1.0" friction="0.0001" />
		<origin rpy="0.00000 -0.00000 0.00000" xyz="0.00000 -0.02202 0.03242" />
		<axis xyz="0.00000 0.00000 0.00000" />
	</joint>
	<joint name="right_inner_knuckle_joint" type="revolute">
		<parent link="robotiq_arg2f_base_link" />
		<child link="right_inner_knuckle" />
		<dynamics damping="0.0" friction="0.0" />
		<origin rpy="0.00000 -0.00000 0.00000" xyz="0.00000 0.01270 0.06142" />
		<axis xyz="1.00000 0.00000 0.00000" />
	<limit effort="1000.0" lower="0.0" upper="0.8757" velocity="2.0" /></joint>
</robot>