<robot name="">
	<link name="world">
		<inertial>
			<origin rpy="0.00000 -0.00000 0.00000" xyz="0.00000 0.00000 0.00000" />
			<mass value="0.00000" />
			<inertia ixx="0.00000" ixy="0" ixz="0" iyy="0.00000" iyz="0" izz="0.00000" />
		</inertial>
	</link>
	<link name="base_link">
		<inertial>
			<origin rpy="0.00000 -0.00000 0.00000" xyz="0.00000 0.00000 0.00000" />
			<mass value="4.00000" />
			<inertia ixx="0.01063" ixy="0" ixz="0" iyy="0.00875" iyz="0" izz="0.01809" />
		</inertial>
		<visual>
			<origin rpy="0.00000 -0.00000 0.00000" xyz="0.00000 0.00000 0.00000" />
			<geometry>
				<mesh filename="rlbotics/envs/models/robots/universal_robots/ur10/meshes/ur10/visual/base.dae" scale="1.00000 1.00000 1.00000" />
			</geometry>
			<material name="0">
				<color rgba="0.70000 0.70000 0.70000 1.00000" />
			</material>
		</visual>
		<collision>
			<origin rpy="0.00000 -0.00000 0.00000" xyz="0.00000 0.00000 0.00000" />
			<geometry>
				<mesh filename="rlbotics/envs/models/robots/universal_robots/ur10/meshes/ur10/collision/base.stl" scale="1.00000 1.00000 1.00000" />
			</geometry>
		</collision>
	</link>
	<link name="shoulder_link">
		<inertial>
			<origin rpy="0.00000 -0.00000 0.00000" xyz="0.00000 0.00000 0.00000" />
			<mass value="7.77800" />
			<inertia ixx="0.03989" ixy="0" ixz="0" iyy="0.03770" iyz="0" izz="0.03412" />
		</inertial>
		<visual>
			<origin rpy="0.00000 -0.00000 0.00000" xyz="0.00000 0.00000 0.00000" />
			<geometry>
				<mesh filename="rlbotics/envs/models/robots/universal_robots/ur10/meshes/ur10/visual/shoulder.dae" scale="1.00000 1.00000 1.00000" />
			</geometry>
			<material name="1">
				<color rgba="0.70000 0.70000 0.70000 1.00000" />
			</material>
		</visual>
		<collision>
			<origin rpy="0.00000 -0.00000 0.00000" xyz="0.00000 0.00000 0.00000" />
			<geometry>
				<mesh filename="rlbotics/envs/models/robots/universal_robots/ur10/meshes/ur10/collision/shoulder.stl" scale="1.00000 1.00000 1.00000" />
			</geometry>
		</collision>
	</link>
	<link name="upper_arm_link">
		<inertial>
			<origin rpy="0.00000 -0.00000 0.00000" xyz="0.00000 -0.04500 0.30600" />
			<mass value="12.93000" />
			<inertia ixx="0.65013" ixy="0" ixz="0" iyy="0.64040" iyz="0" izz="0.06264" />
		</inertial>
		<visual>
			<origin rpy="0.00000 -0.00000 0.00000" xyz="0.00000 0.00000 0.00000" />
			<geometry>
				<mesh filename="rlbotics/envs/models/robots/universal_robots/ur10/meshes/ur10/visual/upperarm.dae" scale="1.00000 1.00000 1.00000" />
			</geometry>
			<material name="2">
				<color rgba="0.70000 0.70000 0.70000 1.00000" />
			</material>
		</visual>
		<collision>
			<origin rpy="0.00000 -0.00000 0.00000" xyz="0.00000 0.00000 0.00000" />
			<geometry>
				<mesh filename="rlbotics/envs/models/robots/universal_robots/ur10/meshes/ur10/collision/upperarm.stl" scale="1.00000 1.00000 1.00000" />
			</geometry>
		</collision>
	</link>
	<link name="forearm_link">
		<inertial>
			<origin rpy="0.00000 -0.00000 0.00000" xyz="0.00000 0.00000 0.28615" />
			<mass value="3.87000" />
			<inertia ixx="0.15749" ixy="0" ixz="0" iyy="0.15609" iyz="0" izz="0.01167" />
		</inertial>
		<visual>
			<origin rpy="0.00000 -0.00000 0.00000" xyz="0.00000 0.00000 0.00000" />
			<geometry>
				<mesh filename="rlbotics/envs/models/robots/universal_robots/ur10/meshes/ur10/visual/forearm.dae" scale="1.00000 1.00000 1.00000" />
			</geometry>
			<material name="3">
				<color rgba="0.70000 0.70000 0.70000 1.00000" />
			</material>
		</visual>
		<collision>
			<origin rpy="0.00000 -0.00000 0.00000" xyz="0.00000 0.00000 0.00000" />
			<geometry>
				<mesh filename="rlbotics/envs/models/robots/universal_robots/ur10/meshes/ur10/collision/forearm.stl" scale="1.00000 1.00000 1.00000" />
			</geometry>
		</collision>
	</link>
	<link name="wrist_1_link">
		<inertial>
			<origin rpy="0.00000 -0.00000 0.00000" xyz="0.00000 0.11490 0.00000" />
			<mass value="1.96000" />
			<inertia ixx="0.00438" ixy="0" ixz="0" iyy="0.00408" iyz="0" izz="0.00338" />
		</inertial>
		<visual>
			<origin rpy="0.00000 -0.00000 0.00000" xyz="0.00000 0.00000 0.00000" />
			<geometry>
				<mesh filename="rlbotics/envs/models/robots/universal_robots/ur10/meshes/ur10/visual/wrist1.dae" scale="1.00000 1.00000 1.00000" />
			</geometry>
			<material name="4">
				<color rgba="0.70000 0.70000 0.70000 1.00000" />
			</material>
		</visual>
		<collision>
			<origin rpy="0.00000 -0.00000 0.00000" xyz="0.00000 0.00000 0.00000" />
			<geometry>
				<mesh filename="rlbotics/envs/models/robots/universal_robots/ur10/meshes/ur10/collision/wrist1.stl" scale="1.00000 1.00000 1.00000" />
			</geometry>
		</collision>
	</link>
	<link name="wrist_2_link">
		<inertial>
			<origin rpy="0.00000 -0.00000 0.00000" xyz="0.00000 0.00000 0.11570" />
			<mass value="1.96000" />
			<inertia ixx="0.00438" ixy="0" ixz="0" iyy="0.00338" iyz="0" izz="0.00409" />
		</inertial>
		<visual>
			<origin rpy="0.00000 -0.00000 0.00000" xyz="0.00000 0.00000 0.00000" />
			<geometry>
				<mesh filename="rlbotics/envs/models/robots/universal_robots/ur10/meshes/ur10/visual/wrist2.dae" scale="1.00000 1.00000 1.00000" />
			</geometry>
			<material name="5">
				<color rgba="0.70000 0.70000 0.70000 1.00000" />
			</material>
		</visual>
		<collision>
			<origin rpy="0.00000 -0.00000 0.00000" xyz="0.00000 0.00000 0.00000" />
			<geometry>
				<mesh filename="rlbotics/envs/models/robots/universal_robots/ur10/meshes/ur10/collision/wrist2.stl" scale="1.00000 1.00000 1.00000" />
			</geometry>
		</collision>
	</link>
	<link name="wrist_3_link">
		<inertial>
			<origin rpy="1.57080 -0.00000 0.00000" xyz="0.00000 0.07695 0.00000" />
			<mass value="0.20200" />
			<inertia ixx="0.00018" ixy="0" ixz="0" iyy="0.00018" iyz="0" izz="0.00031" />
		</inertial>
		<visual>
			<origin rpy="0.00000 -0.00000 0.00000" xyz="0.00000 0.00000 0.00000" />
			<geometry>
				<mesh filename="rlbotics/envs/models/robots/universal_robots/ur10/meshes/ur10/visual/wrist3.dae" scale="1.00000 1.00000 1.00000" />
			</geometry>
			<material name="6">
				<color rgba="0.70000 0.70000 0.70000 1.00000" />
			</material>
		</visual>
		<collision>
			<origin rpy="0.00000 -0.00000 0.00000" xyz="0.00000 0.00000 -0.00000" />
			<geometry>
				<mesh filename="rlbotics/envs/models/robots/universal_robots/ur10/meshes/ur10/collision/wrist3.stl" scale="1.00000 1.00000 1.00000" />
			</geometry>
		</collision>
	</link>
	<link name="ee_link">
		<inertial>
			<origin rpy="0.00000 -0.00000 0.00000" xyz="0.00000 0.00000 0.00000" />
			<mass value="1.00000" />
			<inertia ixx="0.00002" ixy="0" ixz="0" iyy="0.00002" iyz="0" izz="0.00002" />
		</inertial>
		<visual>
			<origin rpy="0.00000 -0.00000 0.00000" xyz="-0.01000 0.00000 0.00000" />
			<geometry>
				<box size="0.01000 0.01000 0.01000" />
			</geometry>
			<material name="7">
				<color rgba="1.00000 1.00000 1.00000 1.00000" />
			</material>
		</visual>
		<collision>
			<origin rpy="0.00000 -0.00000 0.00000" xyz="-0.01000 0.00000 0.00000" />
			<geometry>
				<box size="0.01000 0.01000 0.01000" />
			</geometry>
		</collision>
	</link>
	<link name="tool0">
		<inertial>
			<origin rpy="0.00000 -0.00000 0.00000" xyz="0.00000 0.00000 0.00000" />
			<mass value="1.00000" />
			<inertia ixx="0.00000" ixy="0" ixz="0" iyy="0.00000" iyz="0" izz="0.00000" />
		</inertial>
	</link>
	<link name="base">
		<inertial>
			<origin rpy="0.00000 -0.00000 0.00000" xyz="0.00000 0.00000 0.00000" />
			<mass value="1.00000" />
			<inertia ixx="0.00000" ixy="0" ixz="0" iyy="0.00000" iyz="0" izz="0.00000" />
		</inertial>
	</link>
	<link name="robotiq_arg2f_base_link">
		<inertial>
			<origin rpy="0.00000 -0.00000 0.00000" xyz="0.00000 -0.00000 0.03145" />
			<mass value="0.22652" />
			<inertia ixx="0.00034" ixy="0" ixz="0" iyy="0.00031" iyz="0" izz="0.00028" />
		</inertial>
		<visual>
			<origin rpy="0.00000 -0.00000 0.00000" xyz="0.00000 0.00000 0.00000" />
			<geometry>
				<mesh filename="rlbotics/envs/models/end_effectors/robotiq/robotiq_2f_85/meshes/visual/robotiq_arg2f_85_base_link.dae" scale="0.00100 0.00100 0.00100" />
			</geometry>
			<material name="8">
				<color rgba="0.10000 0.10000 0.10000 1.00000" />
			</material>
		</visual>
		<collision>
			<origin rpy="0.00000 -0.00000 0.00000" xyz="0.00000 0.00000 0.00000" />
			<geometry>
				<mesh filename="rlbotics/envs/models/end_effectors/robotiq/robotiq_2f_85/meshes/collision/robotiq_arg2f_base_link.stl" scale="1.00000 1.00000 1.00000" />
			</geometry>
		</collision>
	</link>
	<link name="left_outer_knuckle">
		<inertial>
			<origin rpy="0.00000 -0.00000 0.00000" xyz="0.00000 0.00000 0.00000" />
			<mass value="1.00000" />
			<inertia ixx="0.00030" ixy="0" ixz="0" iyy="0.00014" iyz="0" izz="0.00030" />
		</inertial>
		<visual>
			<origin rpy="0.00000 -0.00000 0.00000" xyz="0.00000 0.00000 0.00000" />
			<geometry>
				<mesh filename="rlbotics/envs/models/end_effectors/robotiq/robotiq_2f_85/meshes/visual/robotiq_arg2f_85_outer_knuckle.dae" scale="0.00100 0.00100 0.00100" />
			</geometry>
			<material name="9">
				<color rgba="0.79216 0.81961 0.93333 1.00000" />
			</material>
		</visual>
		<collision>
			<origin rpy="0.00000 -0.00000 0.00000" xyz="0.00000 0.00000 0.00000" />
			<geometry>
				<mesh filename="rlbotics/envs/models/end_effectors/robotiq/robotiq_2f_85/meshes/collision/robotiq_arg2f_85_outer_knuckle.dae" scale="0.00100 0.00100 0.00100" />
			</geometry>
		</collision>
	</link>
	<link name="left_outer_finger">
		<inertial>
			<origin rpy="0.00000 -0.00000 0.00000" xyz="0.00000 0.00000 0.00000" />
			<mass value="1.00000" />
			<inertia ixx="0.00040" ixy="0" ixz="0" iyy="0.00044" iyz="0" izz="0.00014" />
		</inertial>
		<visual>
			<origin rpy="0.00000 -0.00000 0.00000" xyz="0.00000 0.00000 0.00000" />
			<geometry>
				<mesh filename="rlbotics/envs/models/end_effectors/robotiq/robotiq_2f_85/meshes/visual/robotiq_arg2f_85_outer_finger.dae" scale="0.00100 0.00100 0.00100" />
			</geometry>
			<material name="10">
				<color rgba="0.10000 0.10000 0.10000 1.00000" />
			</material>
		</visual>
		<collision>
			<origin rpy="0.00000 -0.00000 0.00000" xyz="0.00000 0.00000 0.00000" />
			<geometry>
				<mesh filename="rlbotics/envs/models/end_effectors/robotiq/robotiq_2f_85/meshes/collision/robotiq_arg2f_85_outer_finger.dae" scale="0.00100 0.00100 0.00100" />
			</geometry>
		</collision>
	</link>
	<link name="left_inner_finger">
		<inertial>
			<origin rpy="0.00000 -0.00000 0.00000" xyz="0.00000 0.00000 0.00000" />
			<mass value="1.00000" />
			<inertia ixx="0.00037" ixy="0" ixz="0" iyy="0.00030" iyz="0" izz="0.00014" />
		</inertial>
		<visual>
			<origin rpy="0.00000 -0.00000 0.00000" xyz="0.00000 0.00000 0.00000" />
			<geometry>
				<mesh filename="rlbotics/envs/models/end_effectors/robotiq/robotiq_2f_85/meshes/visual/robotiq_arg2f_85_inner_finger.dae" scale="0.00100 0.00100 0.00100" />
			</geometry>
			<material name="11">
				<color rgba="0.10000 0.10000 0.10000 1.00000" />
			</material>
		</visual>
		<collision>
			<origin rpy="0.00000 -0.00000 0.00000" xyz="0.00000 0.00000 0.00000" />
			<geometry>
				<mesh filename="rlbotics/envs/models/end_effectors/robotiq/robotiq_2f_85/meshes/collision/robotiq_arg2f_85_inner_finger.dae" scale="0.00100 0.00100 0.00100" />
			</geometry>
		</collision>
	</link>
	<link name="left_inner_finger_pad">
		<inertial>
			<origin rpy="0.00000 -0.00000 0.00000" xyz="0.00000 0.00000 0.00000" />
			<mass value="1.00000" />
			<inertia ixx="0.00012" ixy="0" ixz="0" iyy="0.00016" iyz="0" izz="0.00004" />
		</inertial>
		<visual>
			<origin rpy="0.00000 -0.00000 0.00000" xyz="0.00000 0.00000 0.00000" />
			<geometry>
				<box size="0.02200 0.00635 0.03750" />
			</geometry>
			<material name="12">
				<color rgba="0.90000 0.90000 0.90000 1.00000" />
			</material>
		</visual>
		<collision>
			<origin rpy="0.00000 -0.00000 0.00000" xyz="0.00000 0.00000 0.00000" />
			<geometry>
				<box size="0.02200 0.00635 0.03750" />
			</geometry>
		</collision>
	</link>
	<link name="left_inner_knuckle">
		<inertial>
			<origin rpy="0.00000 -0.00000 0.00000" xyz="0.00000 0.00000 0.00000" />
			<mass value="1.00000" />
			<inertia ixx="0.00057" ixy="0" ixz="0" iyy="0.00048" iyz="0" izz="0.00042" />
		</inertial>
		<visual>
			<origin rpy="0.00000 -0.00000 0.00000" xyz="0.00000 0.00000 0.00000" />
			<geometry>
				<mesh filename="rlbotics/envs/models/end_effectors/robotiq/robotiq_2f_85/meshes/visual/robotiq_arg2f_85_inner_knuckle.dae" scale="0.00100 0.00100 0.00100" />
			</geometry>
			<material name="13">
				<color rgba="0.10000 0.10000 0.10000 1.00000" />
			</material>
		</visual>
		<collision>
			<origin rpy="0.00000 -0.00000 0.00000" xyz="0.00000 0.00000 0.00000" />
			<geometry>
				<mesh filename="rlbotics/envs/models/end_effectors/robotiq/robotiq_2f_85/meshes/collision/robotiq_arg2f_85_inner_knuckle.dae" scale="0.00100 0.00100 0.00100" />
			</geometry>
		</collision>
	</link>
	<link name="right_outer_knuckle">
		<inertial>
			<origin rpy="0.00000 -0.00000 0.00000" xyz="0.00000 0.00000 0.00000" />
			<mass value="1.00000" />
			<inertia ixx="0.00030" ixy="0" ixz="0" iyy="0.00014" iyz="0" izz="0.00030" />
		</inertial>
		<visual>
			<origin rpy="0.00000 -0.00000 0.00000" xyz="0.00000 0.00000 0.00000" />
			<geometry>
				<mesh filename="rlbotics/envs/models/end_effectors/robotiq/robotiq_2f_85/meshes/visual/robotiq_arg2f_85_outer_knuckle.dae" scale="0.00100 0.00100 0.00100" />
			</geometry>
			<material name="14">
				<color rgba="0.79216 0.81961 0.93333 1.00000" />
			</material>
		</visual>
		<collision>
			<origin rpy="0.00000 -0.00000 0.00000" xyz="0.00000 0.00000 0.00000" />
			<geometry>
				<mesh filename="rlbotics/envs/models/end_effectors/robotiq/robotiq_2f_85/meshes/collision/robotiq_arg2f_85_outer_knuckle.dae" scale="0.00100 0.00100 0.00100" />
			</geometry>
		</collision>
	</link>
	<link name="right_outer_finger">
		<inertial>
			<origin rpy="0.00000 -0.00000 0.00000" xyz="0.00000 0.00000 0.00000" />
			<mass value="1.00000" />
			<inertia ixx="0.00040" ixy="0" ixz="0" iyy="0.00044" iyz="0" izz="0.00014" />
		</inertial>
		<visual>
			<origin rpy="0.00000 -0.00000 0.00000" xyz="0.00000 0.00000 0.00000" />
			<geometry>
				<mesh filename="rlbotics/envs/models/end_effectors/robotiq/robotiq_2f_85/meshes/visual/robotiq_arg2f_85_outer_finger.dae" scale="0.00100 0.00100 0.00100" />
			</geometry>
			<material name="15">
				<color rgba="0.10000 0.10000 0.10000 1.00000" />
			</material>
		</visual>
		<collision>
			<origin rpy="0.00000 -0.00000 0.00000" xyz="0.00000 0.00000 0.00000" />
			<geometry>
				<mesh filename="rlbotics/envs/models/end_effectors/robotiq/robotiq_2f_85/meshes/collision/robotiq_arg2f_85_outer_finger.dae" scale="0.00100 0.00100 0.00100" />
			</geometry>
		</collision>
	</link>
	<link name="right_inner_finger">
		<inertial>
			<origin rpy="0.00000 -0.00000 0.00000" xyz="0.00000 0.00000 0.00000" />
			<mass value="1.00000" />
			<inertia ixx="0.00037" ixy="0" ixz="0" iyy="0.00030" iyz="0" izz="0.00014" />
		</inertial>
		<visual>
			<origin rpy="0.00000 -0.00000 0.00000" xyz="0.00000 0.00000 0.00000" />
			<geometry>
				<mesh filename="rlbotics/envs/models/end_effectors/robotiq/robotiq_2f_85/meshes/visual/robotiq_arg2f_85_inner_finger.dae" scale="0.00100 0.00100 0.00100" />
			</geometry>
			<material name="16">
				<color rgba="0.10000 0.10000 0.10000 1.00000" />
			</material>
		</visual>
		<collision>
			<origin rpy="0.00000 -0.00000 0.00000" xyz="0.00000 0.00000 0.00000" />
			<geometry>
				<mesh filename="rlbotics/envs/models/end_effectors/robotiq/robotiq_2f_85/meshes/collision/robotiq_arg2f_85_inner_finger.dae" scale="0.00100 0.00100 0.00100" />
			</geometry>
		</collision>
	</link>
	<link name="right_inner_finger_pad">
		<inertial>
			<origin rpy="0.00000 -0.00000 0.00000" xyz="0.00000 0.00000 0.00000" />
			<mass value="1.00000" />
			<inertia ixx="0.00012" ixy="0" ixz="0" iyy="0.00016" iyz="0" izz="0.00004" />
		</inertial>
		<visual>
			<origin rpy="0.00000 -0.00000 0.00000" xyz="0.00000 0.00000 0.00000" />
			<geometry>
				<box size="0.02200 0.00635 0.03750" />
			</geometry>
			<material name="17">
				<color rgba="0.90000 0.90000 0.90000 1.00000" />
			</material>
		</visual>
		<collision>
			<origin rpy="0.00000 -0.00000 0.00000" xyz="0.00000 0.00000 0.00000" />
			<geometry>
				<box size="0.02200 0.00635 0.03750" />
			</geometry>
		</collision>
	</link>
	<link name="right_inner_knuckle">
		<inertial>
			<origin rpy="0.00000 -0.00000 0.00000" xyz="0.00000 0.00000 0.00000" />
			<mass value="1.00000" />
			<inertia ixx="0.00057" ixy="0" ixz="0" iyy="0.00048" iyz="0" izz="0.00042" />
		</inertial>
		<visual>
			<origin rpy="0.00000 -0.00000 0.00000" xyz="0.00000 0.00000 0.00000" />
			<geometry>
				<mesh filename="rlbotics/envs/models/end_effectors/robotiq/robotiq_2f_85/meshes/visual/robotiq_arg2f_85_inner_knuckle.dae" scale="0.00100 0.00100 0.00100" />
			</geometry>
			<material name="18">
				<color rgba="0.10000 0.10000 0.10000 1.00000" />
			</material>
		</visual>
		<collision>
			<origin rpy="0.00000 -0.00000 0.00000" xyz="0.00000 0.00000 0.00000" />
			<geometry>
				<mesh filename="rlbotics/envs/models/end_effectors/robotiq/robotiq_2f_85/meshes/collision/robotiq_arg2f_85_inner_knuckle.dae" scale="0.00100 0.00100 0.00100" />
			</geometry>
		</collision>
	</link>
	<joint name="world_joint" type="fixed">
		<parent link="world" />
		<child link="base_link" />
		<dynamics damping="1.0" friction="0.0001" />
		<origin rpy="0.00000 -0.00000 0.00000" xyz="0.00000 0.00000 0.00000" />
		<axis xyz="0.00000 0.00000 0.00000" />
	</joint>
	<joint name="shoulder_pan_joint" type="revolute">
		<parent link="base_link" />
		<child link="shoulder_link" />
		<dynamics damping="0.0" friction="0.0" />
		<origin rpy="0.00000 -0.00000 0.00000" xyz="0.00000 0.00000 0.12730" />
		<axis xyz="0.00000 0.00000 1.00000" />
	<limit effort="330.0" lower="-6.283185307179586" upper="6.283185307179586" velocity="2.16" /></joint>
	<joint name="shoulder_lift_joint" type="revolute">
		<parent link="shoulder_link" />
		<child link="upper_arm_link" />
		<dynamics damping="0.0" friction="0.0" />
		<origin rpy="0.00000 1.57080 -0.00000" xyz="0.00000 0.22094 0.00000" />
		<axis xyz="0.00000 1.00000 0.00000" />
	<limit effort="330.0" lower="-6.283185307179586" upper="6.283185307179586" velocity="2.16" /></joint>
	<joint name="elbow_joint" type="revolute">
		<parent link="upper_arm_link" />
		<child link="forearm_link" />
		<dynamics damping="0.0" friction="0.0" />
		<origin rpy="0.00000 -0.00000 0.00000" xyz="0.00000 -0.17190 0.61200" />
		<axis xyz="0.00000 1.00000 0.00000" />
	<limit effort="150.0" lower="-3.141592653589793" upper="3.141592653589793" velocity="3.15" /></joint>
	<joint name="wrist_1_joint" type="revolute">
		<parent link="forearm_link" />
		<child link="wrist_1_link" />
		<dynamics damping="0.0" friction="0.0" />
		<origin rpy="0.00000 1.57080 -0.00000" xyz="0.00000 0.00000 0.57230" />
		<axis xyz="0.00000 1.00000 0.00000" />
	<limit effort="54.0" lower="-6.283185307179586" upper="6.283185307179586" velocity="3.2" /></joint>
	<joint name="wrist_2_joint" type="revolute">
		<parent link="wrist_1_link" />
		<child link="wrist_2_link" />
		<dynamics damping="0.0" friction="0.0" />
		<origin rpy="0.00000 -0.00000 0.00000" xyz="0.00000 0.11490 0.00000" />
		<axis xyz="0.00000 0.00000 1.00000" />
	<limit effort="54.0" lower="-6.283185307179586" upper="6.283185307179586" velocity="3.2" /></joint>
	<joint name="wrist_3_joint" type="revolute">
		<parent link="wrist_2_link" />
		<child link="wrist_3_link" />
		<dynamics damping="0.0" friction="0.0" />
		<origin rpy="0.00000 -0.00000 0.00000" xyz="0.00000 0.00000 0.11570" />
		<axis xyz="0.00000 0.00000 -1.00000" />
	<limit effort="54.0" lower="-6.283185307179586" upper="6.283185307179586" velocity="3.2" /></joint>
	<joint name="ee_fixed_joint" type="fixed">
		<parent link="wrist_3_link" />
		<child link="ee_link" />
		<dynamics damping="1.0" friction="0.0001" />
		<origin rpy="0.00000 -0.00000 1.57080" xyz="0.00000 0.09220 0.00000" />
		<axis xyz="0.00000 0.00000 0.00000" />
	</joint>
	<joint name="wrist_3_link-tool0_fixed_joint" type="fixed">
		<parent link="wrist_3_link" />
		<child link="tool0" />
		<dynamics damping="1.0" friction="0.0001" />
		<origin rpy="-1.57080 0.00000 0.00000" xyz="0.00000 0.09220 0.00000" />
		<axis xyz="0.00000 0.00000 0.00000" />
	</joint>
	<joint name="base_link-base_fixed_joint" type="fixed">
		<parent link="base_link" />
		<child link="base" />
		<dynamics damping="1.0" friction="0.0001" />
		<origin rpy="0.00000 -0.00000 -3.14159" xyz="0.00000 0.00000 0.00000" />
		<axis xyz="0.00000 0.00000 0.00000" />
	</joint>
	<joint name="joint_dummy1" type="fixed">
		<parent link="ee_link" />
		<child link="robotiq_arg2f_base_link" />
		<dynamics damping="1.0" friction="0.0001" />
		<origin rpy="0.00000 1.57080 0.00000" xyz="0.00000 0.00000 0.00000" />
		<axis xyz="0.00000 0.00000 1.00000" />
	</joint>
	<joint name="finger_joint" type="revolute">
		<parent link="robotiq_arg2f_base_link" />
		<child link="left_outer_knuckle" />
		<dynamics damping="0.0" friction="0.0" />
		<origin rpy="0.00000 -0.00000 3.14159" xyz="0.00000 -0.03060 0.05490" />
		<axis xyz="1.00000 0.00000 0.00000" />
	<limit effort="1000.0" lower="0.0" upper="0.8" velocity="2.0" /></joint>
	<joint name="left_outer_finger_joint" type="fixed">
		<parent link="left_outer_knuckle" />
		<child link="left_outer_finger" />
		<dynamics damping="1.0" friction="0.0001" />
		<origin rpy="0.00000 -0.00000 0.00000" xyz="0.00000 0.03150 -0.00410" />
		<axis xyz="0.00000 0.00000 0.00000" />
	</joint>
	<joint name="left_inner_finger_joint" type="revolute">
		<parent link="left_outer_finger" />
		<child link="left_inner_finger" />
		<dynamics damping="0.0" friction="0.0" />
		<origin rpy="0.00000 -0.00000 0.00000" xyz="0.00000 0.00610 0.04710" />
		<axis xyz="1.00000 0.00000 0.00000" />
	<limit effort="1000.0" lower="0.0" upper="0.8757" velocity="2.0" /></joint>
	<joint name="left_inner_finger_pad_joint" type="fixed">
		<parent link="left_inner_finger" />
		<child link="left_inner_finger_pad" />
		<dynamics damping="1.0" friction="0.0001" />
		<origin rpy="0.00000 -0.00000 0.00000" xyz="0.00000 -0.02202 0.03242" />
		<axis xyz="0.00000 0.00000 0.00000" />
	</joint>
	<joint name="left_inner_knuckle_joint" type="revolute">
		<parent link="robotiq_arg2f_base_link" />
		<child link="left_inner_knuckle" />
		<dynamics damping="0.0" friction="0.0" />
		<origin rpy="0.00000 -0.00000 3.14159" xyz="0.00000 -0.01270 0.06142" />
		<axis xyz="1.00000 0.00000 0.00000" />
	<limit effort="1000.0" lower="0.0" upper="0.8757" velocity="2.0" /></joint>
	<joint name="right_outer_knuckle_joint" type="revolute">
		<parent link="robotiq_arg2f_base_link" />
		<child link="right_outer_knuckle" />
		<dynamics damping="0.0" friction="0.0" />
		<origin rpy="0.00000 -0.00000 0.00000" xyz="0.00000 0.03060 0.05490" />
		<axis xyz="1.00000 0.00000 0.00000" />
	<limit effort="1000.0" lower="0.0" upper="0.81" velocity="2.0" /></joint>
	<joint name="right_outer_finger_joint" type="fixed">
		<parent link="right_outer_knuckle" />
		<child link="right_outer_finger" />
		<dynamics damping="1.0" friction="0.0001" />
		<origin rpy="0.00000 -0.00000 0.00000" xyz="0.00000 0.03150 -0.00410" />
		<axis xyz="0.00000 0.00000 0.00000" />
	</joint>
	<joint name="right_inner_finger_joint" type="revolute">
		<parent link="right_outer_finger" />
		<child link="right_inner_finger" />
		<dynamics damping="0.0" friction="0.0" />
		<origin rpy="0.00000 -0.00000 0.00000" xyz="0.00000 0.00610 0.04710" />
		<axis xyz="1.00000 0.00000 0.00000" />
	<limit effort="1000.0" lower="0.0" upper="0.8757" velocity="2.0" /></joint>
	<joint name="right_inner_finger_pad_joint" type="fixed">
		<parent link="right_inner_finger" />
		<child link="right_inner_finger_pad" />
		<dynamics damping="1.0" friction="0.0001" />
		<origin rpy="0.00000 -0.00000 0.00000" xyz="0.00000 -0.02202 0.03242" />
		<axis xyz="0.00000 0.00000 0.00000" />
	</joint>
	<joint name="right_inner_knuckle_joint" type="revolute">
		<parent link="robotiq_arg2f_base_link" />
		<child link="right_inner_knuckle" />
		<dynamics damping="0.0" friction="0.0" />
		<origin rpy="0.00000 -0.00000 0.00000" xyz="0.00000 0.01270 0.06142" />
		<axis xyz="1.00000 0.00000 0.00000" />
	<limit effort="1000.0" lower="0.0" upper="0.8757" velocity="2.0" /></joint>
</robot>