<?xml version="0.0" ?>
<robot name="">
	<link name="world">
		<inertial>
			<origin rpy="0.00000 -0.00000 0.00000" xyz="0.00000 0.00000 0.00000"/>
			<mass value="0.00000"/>
			<inertia ixx="0.00000" ixy="0" ixz="0" iyy="0.00000" iyz="0" izz="0.00000"/>
		</inertial>
	</link>
	<link name="base_link">
		<inertial>
			<origin rpy="0.00000 -0.00000 0.00000" xyz="0.00000 0.00000 0.00000"/>
			<mass value="4.00000"/>
			<inertia ixx="0.01228" ixy="0" ixz="0" iyy="0.00812" iyz="0" izz="0.01980"/>
		</inertial>
		<visual>
			<origin rpy="0.00000 -0.00000 0.00000" xyz="0.00000 0.00000 0.00000"/>
			<geometry>
				<mesh filename="rlbotics\envs\models\robots/universal_robots/ur5/meshes/visual/base.dae" scale="1.00000 1.00000 1.00000"/>
			</geometry>
			<material name="mat_0_0">
				<color rgba="0.70000 0.70000 0.70000 1.00000" />
			</material>
		</visual>
		<collision>
			<origin rpy="0.00000 -0.00000 0.00000" xyz="0.00000 0.00000 0.00000"/>
			<geometry>
				<mesh filename="rlbotics\envs\models\robots/universal_robots/ur5/meshes/collision/base.stl" scale="1.00000 1.00000 1.00000"/>
			</geometry>
		</collision>
	</link>
	<link name="shoulder_link">
		<inertial>
			<origin rpy="0.00000 -0.00000 0.00000" xyz="0.00000 0.00000 0.00000"/>
			<mass value="3.70000"/>
			<inertia ixx="0.01174" ixy="0" ixz="0" iyy="0.01082" iyz="0" izz="0.01053"/>
		</inertial>
		<visual>
			<origin rpy="0.00000 -0.00000 0.00000" xyz="0.00000 0.00000 0.00000"/>
			<geometry>
				<mesh filename="rlbotics\envs\models\robots/universal_robots/ur5/meshes/visual/shoulder.dae" scale="1.00000 1.00000 1.00000"/>
			</geometry>
			<material name="mat_1_0">
				<color rgba="0.70000 0.70000 0.70000 1.00000" />
			</material>
		</visual>
		<collision>
			<origin rpy="0.00000 -0.00000 0.00000" xyz="0.00000 0.00000 0.00000"/>
			<geometry>
				<mesh filename="rlbotics\envs\models\robots/universal_robots/ur5/meshes/collision/shoulder.stl" scale="1.00000 1.00000 1.00000"/>
			</geometry>
		</collision>
	</link>
	<link name="upper_arm_link">
		<inertial>
			<origin rpy="0.00000 -0.00000 0.00000" xyz="0.00000 0.00000 0.28000"/>
			<mass value="8.39300"/>
			<inertia ixx="0.22574" ixy="0" ixz="0" iyy="0.22306" iyz="0" izz="0.02466"/>
		</inertial>
		<visual>
			<origin rpy="0.00000 -0.00000 0.00000" xyz="0.00000 0.00000 0.00000"/>
			<geometry>
				<mesh filename="rlbotics\envs\models\robots/universal_robots/ur5/meshes/visual/upperarm.dae" scale="1.00000 1.00000 1.00000"/>
			</geometry>
			<material name="mat_2_0">
				<color rgba="0.70000 0.70000 0.70000 1.00000" />
			</material>
		</visual>
		<collision>
			<origin rpy="0.00000 -0.00000 0.00000" xyz="0.00000 0.00000 0.00000"/>
			<geometry>
				<mesh filename="rlbotics\envs\models\robots/universal_robots/ur5/meshes/collision/upperarm.stl" scale="1.00000 1.00000 1.00000"/>
			</geometry>
		</collision>
	</link>
	<link name="forearm_link">
		<inertial>
			<origin rpy="0.00000 -0.00000 0.00000" xyz="0.00000 0.00000 0.19612"/>
			<mass value="2.27500"/>
			<inertia ixx="0.04913" ixy="0" ixz="0" iyy="0.04934" iyz="0" izz="0.00547"/>
		</inertial>
		<visual>
			<origin rpy="0.00000 -0.00000 0.00000" xyz="0.00000 0.00000 0.00000"/>
			<geometry>
				<mesh filename="rlbotics\envs\models\robots/universal_robots/ur5/meshes/visual/forearm.dae" scale="1.00000 1.00000 1.00000"/>
			</geometry>
			<material name="mat_3_0">
				<color rgba="0.70000 0.70000 0.70000 1.00000" />
			</material>
		</visual>
		<collision>
			<origin rpy="0.00000 -0.00000 0.00000" xyz="0.00000 0.00000 0.00000"/>
			<geometry>
				<mesh filename="rlbotics\envs\models\robots/universal_robots/ur5/meshes/collision/forearm.stl" scale="1.00000 1.00000 1.00000"/>
			</geometry>
		</collision>
	</link>
	<link name="wrist_1_link">
		<inertial>
			<origin rpy="0.00000 -0.00000 0.00000" xyz="0.00000 0.09300 0.00000"/>
			<mass value="1.21900"/>
			<inertia ixx="0.00209" ixy="0" ixz="0" iyy="0.00195" iyz="0" izz="0.00155"/>
		</inertial>
		<visual>
			<origin rpy="0.00000 -0.00000 0.00000" xyz="0.00000 0.00000 0.00000"/>
			<geometry>
				<mesh filename="rlbotics\envs\models\robots/universal_robots/ur5/meshes/visual/wrist1.dae" scale="1.00000 1.00000 1.00000"/>
			</geometry>
			<material name="mat_4_0">
				<color rgba="0.70000 0.70000 0.70000 1.00000" />
			</material>
		</visual>
		<collision>
			<origin rpy="0.00000 -0.00000 0.00000" xyz="0.00000 0.00000 0.00000"/>
			<geometry>
				<mesh filename="rlbotics\envs\models\robots/universal_robots/ur5/meshes/collision/wrist1.stl" scale="1.00000 1.00000 1.00000"/>
			</geometry>
		</collision>
	</link>
	<link name="wrist_2_link">
		<inertial>
			<origin rpy="0.00000 -0.00000 0.00000" xyz="0.00000 0.00000 0.09465"/>
			<mass value="1.21900"/>
			<inertia ixx="0.00207" ixy="0" ixz="0" iyy="0.00154" iyz="0" izz="0.00195"/>
		</inertial>
		<visual>
			<origin rpy="0.00000 -0.00000 0.00000" xyz="0.00000 0.00000 0.00000"/>
			<geometry>
				<mesh filename="rlbotics\envs\models\robots/universal_robots/ur5/meshes/visual/wrist2.dae" scale="1.00000 1.00000 1.00000"/>
			</geometry>
			<material name="mat_5_0">
				<color rgba="0.70000 0.70000 0.70000 1.00000" />
			</material>
		</visual>
		<collision>
			<origin rpy="0.00000 -0.00000 0.00000" xyz="0.00000 0.00000 0.00000"/>
			<geometry>
				<mesh filename="rlbotics\envs\models\robots/universal_robots/ur5/meshes/collision/wrist2.stl" scale="1.00000 1.00000 1.00000"/>
			</geometry>
		</collision>
	</link>
	<link name="wrist_3_link">
		<inertial>
			<origin rpy="1.57080 -0.00000 0.00000" xyz="0.00000 0.06505 0.00000"/>
			<mass value="0.18790"/>
			<inertia ixx="0.00014" ixy="0" ixz="0" iyy="0.00013" iyz="0" izz="0.00022"/>
		</inertial>
		<visual>
			<origin rpy="0.00000 -0.00000 0.00000" xyz="0.00000 0.00000 0.00000"/>
			<geometry>
				<mesh filename="rlbotics\envs\models\robots/universal_robots/ur5/meshes/visual/wrist3.dae" scale="1.00000 1.00000 1.00000"/>
			</geometry>
			<material name="mat_6_0">
				<color rgba="0.70000 0.70000 0.70000 1.00000" />
			</material>
		</visual>
		<collision>
			<origin rpy="0.00000 -0.00000 0.00000" xyz="0.00000 0.00000 0.00000"/>
			<geometry>
				<mesh filename="rlbotics\envs\models\robots/universal_robots/ur5/meshes/collision/wrist3.stl" scale="1.00000 1.00000 1.00000"/>
			</geometry>
		</collision>
	</link>
	<link name="ee_link">
		<inertial>
			<origin rpy="0.00000 -0.00000 0.00000" xyz="0.00000 0.00000 0.00000"/>
			<mass value="1.00000"/>
			<inertia ixx="0.00002" ixy="0" ixz="0" iyy="0.00002" iyz="0" izz="0.00002"/>
		</inertial>
		<visual>
			<origin rpy="0.00000 -0.00000 0.00000" xyz="-0.01000 0.00000 0.00000"/>
			<geometry>
				<box size="0.01000 0.01000 0.01000"/>
			</geometry>
			<material name="mat_7_0">
				<color rgba="1.00000 1.00000 1.00000 1.00000" />
			</material>
		</visual>
		<collision>
			<origin rpy="0.00000 -0.00000 0.00000" xyz="-0.01000 0.00000 0.00000"/>
			<geometry>
				<box size="0.01000 0.01000 0.01000"/>
			</geometry>
		</collision>
	</link>
	<link name="tool0">
		<inertial>
			<origin rpy="0.00000 -0.00000 0.00000" xyz="0.00000 0.00000 0.00000"/>
			<mass value="1.00000"/>
			<inertia ixx="0.00000" ixy="0" ixz="0" iyy="0.00000" iyz="0" izz="0.00000"/>
		</inertial>
	</link>
	<link name="base">
		<inertial>
			<origin rpy="0.00000 -0.00000 0.00000" xyz="0.00000 0.00000 0.00000"/>
			<mass value="1.00000"/>
			<inertia ixx="0.00000" ixy="0" ixz="0" iyy="0.00000" iyz="0" izz="0.00000"/>
		</inertial>
	</link>
	<link name="robotiq_arg2f_base_link">
		<inertial>
			<origin rpy="0.00000 -0.00000 0.00000" xyz="0.00000 -0.00000 0.03145"/>
			<mass value="0.22652"/>
			<inertia ixx="0.00034" ixy="0" ixz="0" iyy="0.00031" iyz="0" izz="0.00028"/>
		</inertial>
		<visual>
			<origin rpy="0.00000 -0.00000 0.00000" xyz="0.00000 0.00000 0.00000"/>
			<geometry>
				<mesh filename="rlbotics\envs\models\grippers/robotiq/robotiq_2f_85/meshes/visual/robotiq_arg2f_85_base_link.dae" scale="0.00100 0.00100 0.00100"/>
			</geometry>
			<material name="mat_-1_0">
				<color rgba="0.10000 0.10000 0.10000 1.00000" />
			</material>
		</visual>
		<collision>
			<origin rpy="0.00000 -0.00000 0.00000" xyz="0.00000 0.00000 0.00000"/>
			<geometry>
				<mesh filename="rlbotics\envs\models\grippers/robotiq/robotiq_2f_85/meshes/collision/robotiq_arg2f_base_link.stl" scale="1.00000 1.00000 1.00000"/>
			</geometry>
		</collision>
	</link>
	<link name="left_outer_knuckle">
		<inertial>
			<origin rpy="0.00000 -0.00000 0.00000" xyz="0.00000 0.00000 0.00000"/>
			<mass value="1.00000"/>
			<inertia ixx="0.00030" ixy="0" ixz="0" iyy="0.00014" iyz="0" izz="0.00030"/>
		</inertial>
		<visual>
			<origin rpy="0.00000 -0.00000 0.00000" xyz="0.00000 0.00000 0.00000"/>
			<geometry>
				<mesh filename="rlbotics\envs\models\grippers/robotiq/robotiq_2f_85/meshes/visual/robotiq_arg2f_85_outer_knuckle.dae" scale="0.00100 0.00100 0.00100"/>
			</geometry>
			<material name="mat_0_0">
				<color rgba="0.10000 0.10000 0.10000 1.00000" />
			</material>
		</visual>
		<collision>
			<origin rpy="0.00000 -0.00000 0.00000" xyz="0.00000 0.00000 0.00000"/>
			<geometry>
				<mesh filename="rlbotics\envs\models\grippers/robotiq/robotiq_2f_85/meshes/collision/robotiq_arg2f_85_outer_knuckle.dae" scale="0.00100 0.00100 0.00100"/>
			</geometry>
		</collision>
	</link>
	<link name="left_outer_finger">
		<inertial>
			<origin rpy="0.00000 -0.00000 0.00000" xyz="0.00000 0.00000 0.00000"/>
			<mass value="1.00000"/>
			<inertia ixx="0.00040" ixy="0" ixz="0" iyy="0.00044" iyz="0" izz="0.00014"/>
		</inertial>
		<visual>
			<origin rpy="0.00000 -0.00000 0.00000" xyz="0.00000 0.00000 0.00000"/>
			<geometry>
				<mesh filename="rlbotics\envs\models\grippers/robotiq/robotiq_2f_85/meshes/visual/robotiq_arg2f_85_outer_finger.dae" scale="0.00100 0.00100 0.00100"/>
			</geometry>
			<material name="mat_1_0">
				<color rgba="0.10000 0.10000 0.10000 1.00000" />
			</material>
		</visual>
		<collision>
			<origin rpy="0.00000 -0.00000 0.00000" xyz="0.00000 0.00000 0.00000"/>
			<geometry>
				<mesh filename="rlbotics\envs\models\grippers/robotiq/robotiq_2f_85/meshes/collision/robotiq_arg2f_85_outer_finger.dae" scale="0.00100 0.00100 0.00100"/>
			</geometry>
		</collision>
	</link>
	<link name="left_inner_finger">
		<inertial>
			<origin rpy="0.00000 -0.00000 0.00000" xyz="0.00000 0.00000 0.00000"/>
			<mass value="1.00000"/>
			<inertia ixx="0.00037" ixy="0" ixz="0" iyy="0.00030" iyz="0" izz="0.00014"/>
		</inertial>
		<visual>
			<origin rpy="0.00000 -0.00000 0.00000" xyz="0.00000 0.00000 0.00000"/>
			<geometry>
				<mesh filename="rlbotics\envs\models\grippers/robotiq/robotiq_2f_85/meshes/visual/robotiq_arg2f_85_inner_finger.dae" scale="0.00100 0.00100 0.00100"/>
			</geometry>
			<material name="mat_2_0">
				<color rgba="0.10000 0.10000 0.10000 1.00000" />
			</material>
		</visual>
		<collision>
			<origin rpy="0.00000 -0.00000 0.00000" xyz="0.00000 0.00000 0.00000"/>
			<geometry>
				<mesh filename="rlbotics\envs\models\grippers/robotiq/robotiq_2f_85/meshes/collision/robotiq_arg2f_85_inner_finger.dae" scale="0.00100 0.00100 0.00100"/>
			</geometry>
		</collision>
	</link>
	<link name="left_inner_finger_pad">
		<inertial>
			<origin rpy="0.00000 -0.00000 0.00000" xyz="0.00000 0.00000 0.00000"/>
			<mass value="1.00000"/>
			<inertia ixx="0.00012" ixy="0" ixz="0" iyy="0.00016" iyz="0" izz="0.00004"/>
		</inertial>
		<visual>
			<origin rpy="0.00000 -0.00000 0.00000" xyz="0.00000 0.00000 0.00000"/>
			<geometry>
				<box size="0.02200 0.00635 0.03750"/>
			</geometry>
			<material name="mat_3_0">
				<color rgba="0.10000 0.10000 0.10000 1.00000" />
			</material>
		</visual>
		<collision>
			<origin rpy="0.00000 -0.00000 0.00000" xyz="0.00000 0.00000 0.00000"/>
			<geometry>
				<box size="0.02200 0.00635 0.03750"/>
			</geometry>
		</collision>
	</link>
	<link name="left_inner_knuckle">
		<inertial>
			<origin rpy="0.00000 -0.00000 0.00000" xyz="0.00000 0.00000 0.00000"/>
			<mass value="1.00000"/>
			<inertia ixx="0.00057" ixy="0" ixz="0" iyy="0.00048" iyz="0" izz="0.00042"/>
		</inertial>
		<visual>
			<origin rpy="0.00000 -0.00000 0.00000" xyz="0.00000 0.00000 0.00000"/>
			<geometry>
				<mesh filename="rlbotics\envs\models\grippers/robotiq/robotiq_2f_85/meshes/visual/robotiq_arg2f_85_inner_knuckle.dae" scale="0.00100 0.00100 0.00100"/>
			</geometry>
			<material name="mat_4_0">
				<color rgba="0.10000 0.10000 0.10000 1.00000" />
			</material>
		</visual>
		<collision>
			<origin rpy="0.00000 -0.00000 0.00000" xyz="0.00000 0.00000 0.00000"/>
			<geometry>
				<mesh filename="rlbotics\envs\models\grippers/robotiq/robotiq_2f_85/meshes/collision/robotiq_arg2f_85_inner_knuckle.dae" scale="0.00100 0.00100 0.00100"/>
			</geometry>
		</collision>
	</link>
	<link name="right_outer_knuckle">
		<inertial>
			<origin rpy="0.00000 -0.00000 0.00000" xyz="0.00000 0.00000 0.00000"/>
			<mass value="1.00000"/>
			<inertia ixx="0.00030" ixy="0" ixz="0" iyy="0.00014" iyz="0" izz="0.00030"/>
		</inertial>
		<visual>
			<origin rpy="0.00000 -0.00000 0.00000" xyz="0.00000 0.00000 0.00000"/>
			<geometry>
				<mesh filename="rlbotics\envs\models\grippers/robotiq/robotiq_2f_85/meshes/visual/robotiq_arg2f_85_outer_knuckle.dae" scale="0.00100 0.00100 0.00100"/>
			</geometry>
			<material name="mat_5_0">
				<color rgba="0.10000 0.10000 0.10000 1.00000" />
			</material>
		</visual>
		<collision>
			<origin rpy="0.00000 -0.00000 0.00000" xyz="0.00000 0.00000 0.00000"/>
			<geometry>
				<mesh filename="rlbotics\envs\models\grippers/robotiq/robotiq_2f_85/meshes/collision/robotiq_arg2f_85_outer_knuckle.dae" scale="0.00100 0.00100 0.00100"/>
			</geometry>
		</collision>
	</link>
	<link name="right_outer_finger">
		<inertial>
			<origin rpy="0.00000 -0.00000 0.00000" xyz="0.00000 0.00000 0.00000"/>
			<mass value="1.00000"/>
			<inertia ixx="0.00040" ixy="0" ixz="0" iyy="0.00044" iyz="0" izz="0.00014"/>
		</inertial>
		<visual>
			<origin rpy="0.00000 -0.00000 0.00000" xyz="0.00000 0.00000 0.00000"/>
			<geometry>
				<mesh filename="rlbotics\envs\models\grippers/robotiq/robotiq_2f_85/meshes/visual/robotiq_arg2f_85_outer_finger.dae" scale="0.00100 0.00100 0.00100"/>
			</geometry>
			<material name="mat_6_0">
				<color rgba="0.10000 0.10000 0.10000 1.00000" />
			</material>
		</visual>
		<collision>
			<origin rpy="0.00000 -0.00000 0.00000" xyz="0.00000 0.00000 0.00000"/>
			<geometry>
				<mesh filename="rlbotics\envs\models\grippers/robotiq/robotiq_2f_85/meshes/collision/robotiq_arg2f_85_outer_finger.dae" scale="0.00100 0.00100 0.00100"/>
			</geometry>
		</collision>
	</link>
	<link name="right_inner_finger">
		<inertial>
			<origin rpy="0.00000 -0.00000 0.00000" xyz="0.00000 0.00000 0.00000"/>
			<mass value="1.00000"/>
			<inertia ixx="0.00037" ixy="0" ixz="0" iyy="0.00030" iyz="0" izz="0.00014"/>
		</inertial>
		<visual>
			<origin rpy="0.00000 -0.00000 0.00000" xyz="0.00000 0.00000 0.00000"/>
			<geometry>
				<mesh filename="rlbotics\envs\models\grippers/robotiq/robotiq_2f_85/meshes/visual/robotiq_arg2f_85_inner_finger.dae" scale="0.00100 0.00100 0.00100"/>
			</geometry>
			<material name="mat_7_0">
				<color rgba="0.10000 0.10000 0.10000 1.00000" />
			</material>
		</visual>
		<collision>
			<origin rpy="0.00000 -0.00000 0.00000" xyz="0.00000 0.00000 0.00000"/>
			<geometry>
				<mesh filename="rlbotics\envs\models\grippers/robotiq/robotiq_2f_85/meshes/collision/robotiq_arg2f_85_inner_finger.dae" scale="0.00100 0.00100 0.00100"/>
			</geometry>
		</collision>
	</link>
	<link name="right_inner_finger_pad">
		<inertial>
			<origin rpy="0.00000 -0.00000 0.00000" xyz="0.00000 0.00000 0.00000"/>
			<mass value="1.00000"/>
			<inertia ixx="0.00012" ixy="0" ixz="0" iyy="0.00016" iyz="0" izz="0.00004"/>
		</inertial>
		<visual>
			<origin rpy="0.00000 -0.00000 0.00000" xyz="0.00000 0.00000 0.00000"/>
			<geometry>
				<box size="0.02200 0.00635 0.03750"/>
			</geometry>
			<material name="mat_8_0">
				<color rgba="0.10000 0.10000 0.10000 1.00000" />
			</material>
		</visual>
		<collision>
			<origin rpy="0.00000 -0.00000 0.00000" xyz="0.00000 0.00000 0.00000"/>
			<geometry>
				<box size="0.02200 0.00635 0.03750"/>
			</geometry>
		</collision>
	</link>
	<link name="right_inner_knuckle">
		<inertial>
			<origin rpy="0.00000 -0.00000 0.00000" xyz="0.00000 0.00000 0.00000"/>
			<mass value="1.00000"/>
			<inertia ixx="0.00057" ixy="0" ixz="0" iyy="0.00048" iyz="0" izz="0.00042"/>
		</inertial>
		<visual>
			<origin rpy="0.00000 -0.00000 0.00000" xyz="0.00000 0.00000 0.00000"/>
			<geometry>
				<mesh filename="rlbotics\envs\models\grippers/robotiq/robotiq_2f_85/meshes/visual/robotiq_arg2f_85_inner_knuckle.dae" scale="0.00100 0.00100 0.00100"/>
			</geometry>
			<material name="mat_9_0">
				<color rgba="0.10000 0.10000 0.10000 1.00000" />
			</material>
		</visual>
		<collision>
			<origin rpy="0.00000 -0.00000 0.00000" xyz="0.00000 0.00000 0.00000"/>
			<geometry>
				<mesh filename="rlbotics\envs\models\grippers/robotiq/robotiq_2f_85/meshes/collision/robotiq_arg2f_85_inner_knuckle.dae" scale="0.00100 0.00100 0.00100"/>
			</geometry>
		</collision>
	</link>
	<joint name="world_joint" type="fixed">
		<parent link="world"/>
		<child link="base_link"/>
		<dynamics damping="1.0" friction="0.0001"/>
		<origin rpy="0.00000 -0.00000 0.00000" xyz="0.00000 0.00000 0.00000"/>
		<axis xyz="0.00000 0.00000 0.00000"/>
	</joint>
	<joint name="shoulder_pan_joint" type="continuous">
		<parent link="base_link"/>
		<child link="shoulder_link"/>
		<dynamics damping="1.0" friction="0.0001"/>
		<origin rpy="0.00000 -0.00000 0.00000" xyz="0.00000 0.00000 0.08916"/>
		<axis xyz="0.00000 0.00000 1.00000"/>
	</joint>
	<joint name="shoulder_lift_joint" type="continuous">
		<parent link="shoulder_link"/>
		<child link="upper_arm_link"/>
		<dynamics damping="1.0" friction="0.0001"/>
		<origin rpy="0.00000 1.57080 -0.00000" xyz="0.00000 0.13585 0.00000"/>
		<axis xyz="0.00000 1.00000 0.00000"/>
	</joint>
	<joint name="elbow_joint" type="continuous">
		<parent link="upper_arm_link"/>
		<child link="forearm_link"/>
		<dynamics damping="1.0" friction="0.0001"/>
		<origin rpy="0.00000 -0.00000 0.00000" xyz="0.00000 -0.11970 0.42500"/>
		<axis xyz="0.00000 1.00000 0.00000"/>
	</joint>
	<joint name="wrist_1_joint" type="continuous">
		<parent link="forearm_link"/>
		<child link="wrist_1_link"/>
		<dynamics damping="1.0" friction="0.0001"/>
		<origin rpy="0.00000 1.57080 -0.00000" xyz="0.00000 0.00000 0.39225"/>
		<axis xyz="0.00000 1.00000 0.00000"/>
	</joint>
	<joint name="wrist_2_joint" type="continuous">
		<parent link="wrist_1_link"/>
		<child link="wrist_2_link"/>
		<dynamics damping="1.0" friction="0.0001"/>
		<origin rpy="0.00000 -0.00000 0.00000" xyz="0.00000 0.09300 0.00000"/>
		<axis xyz="0.00000 0.00000 1.00000"/>
	</joint>
	<joint name="wrist_3_joint" type="continuous">
		<parent link="wrist_2_link"/>
		<child link="wrist_3_link"/>
		<dynamics damping="1.0" friction="0.0001"/>
		<origin rpy="0.00000 -0.00000 0.00000" xyz="0.00000 0.00000 0.09465"/>
		<axis xyz="0.00000 0.00000 -1.00000"/>
	</joint>
	<joint name="ee_fixed_joint" type="fixed">
		<parent link="wrist_3_link"/>
		<child link="ee_link"/>
		<dynamics damping="1.0" friction="0.0001"/>
		<origin rpy="0.00000 -0.00000 1.57080" xyz="0.00000 0.08230 0.00000"/>
		<axis xyz="0.00000 0.00000 0.00000"/>
	</joint>
	<joint name="wrist_3_link-tool0_fixed_joint" type="fixed">
		<parent link="wrist_3_link"/>
		<child link="tool0"/>
		<dynamics damping="1.0" friction="0.0001"/>
		<origin rpy="-1.57080 0.00000 0.00000" xyz="0.00000 0.08230 0.00000"/>
		<axis xyz="0.00000 0.00000 0.00000"/>
	</joint>
	<joint name="base_link-base_fixed_joint" type="fixed">
		<parent link="base_link"/>
		<child link="base"/>
		<dynamics damping="1.0" friction="0.0001"/>
		<origin rpy="0.00000 -0.00000 -3.14159" xyz="0.00000 0.00000 0.00000"/>
		<axis xyz="0.00000 0.00000 0.00000"/>
	</joint>
	<joint name="joint_dummy1" type="fixed">
		<parent link="ee_link"/>
		<child link="robotiq_arg2f_base_link"/>
		<dynamics damping="1.0" friction="0.0001"/>
		<origin rpy="0.00000 1.57080 0.00000" xyz="0.00000 0.00000 0.00000"/>
		<axis xyz="0.00000 0.00000 1.00000"/>
	</joint>
	<joint name="finger_joint" type="continuous">
		<parent link="robotiq_arg2f_base_link"/>
		<child link="left_outer_knuckle"/>
		<dynamics damping="1.0" friction="0.0001"/>
		<origin rpy="0.00000 -0.00000 3.14159" xyz="0.00000 -0.03060 0.05490"/>
		<axis xyz="1.00000 0.00000 0.00000"/>
	</joint>
	<joint name="left_outer_finger_joint" type="fixed">
		<parent link="left_outer_knuckle"/>
		<child link="left_outer_finger"/>
		<dynamics damping="1.0" friction="0.0001"/>
		<origin rpy="0.00000 -0.00000 0.00000" xyz="0.00000 0.03150 -0.00410"/>
		<axis xyz="0.00000 0.00000 0.00000"/>
	</joint>
	<joint name="left_inner_finger_joint" type="continuous">
		<parent link="left_outer_finger"/>
		<child link="left_inner_finger"/>
		<dynamics damping="1.0" friction="0.0001"/>
		<origin rpy="0.00000 -0.00000 0.00000" xyz="0.00000 0.00610 0.04710"/>
		<axis xyz="1.00000 0.00000 0.00000"/>
	</joint>
	<joint name="left_inner_finger_pad_joint" type="fixed">
		<parent link="left_inner_finger"/>
		<child link="left_inner_finger_pad"/>
		<dynamics damping="1.0" friction="0.0001"/>
		<origin rpy="0.00000 -0.00000 0.00000" xyz="0.00000 -0.02202 0.03242"/>
		<axis xyz="0.00000 0.00000 0.00000"/>
	</joint>
	<joint name="left_inner_knuckle_joint" type="continuous">
		<parent link="robotiq_arg2f_base_link"/>
		<child link="left_inner_knuckle"/>
		<dynamics damping="1.0" friction="0.0001"/>
		<origin rpy="0.00000 -0.00000 3.14159" xyz="0.00000 -0.01270 0.06142"/>
		<axis xyz="1.00000 0.00000 0.00000"/>
	</joint>
	<joint name="right_outer_knuckle_joint" type="continuous">
		<parent link="robotiq_arg2f_base_link"/>
		<child link="right_outer_knuckle"/>
		<dynamics damping="1.0" friction="0.0001"/>
		<origin rpy="0.00000 -0.00000 0.00000" xyz="0.00000 0.03060 0.05490"/>
		<axis xyz="1.00000 0.00000 0.00000"/>
	</joint>
	<joint name="right_outer_finger_joint" type="fixed">
		<parent link="right_outer_knuckle"/>
		<child link="right_outer_finger"/>
		<dynamics damping="1.0" friction="0.0001"/>
		<origin rpy="0.00000 -0.00000 0.00000" xyz="0.00000 0.03150 -0.00410"/>
		<axis xyz="0.00000 0.00000 0.00000"/>
	</joint>
	<joint name="right_inner_finger_joint" type="continuous">
		<parent link="right_outer_finger"/>
		<child link="right_inner_finger"/>
		<dynamics damping="1.0" friction="0.0001"/>
		<origin rpy="0.00000 -0.00000 0.00000" xyz="0.00000 0.00610 0.04710"/>
		<axis xyz="1.00000 0.00000 0.00000"/>
	</joint>
	<joint name="right_inner_finger_pad_joint" type="fixed">
		<parent link="right_inner_finger"/>
		<child link="right_inner_finger_pad"/>
		<dynamics damping="1.0" friction="0.0001"/>
		<origin rpy="0.00000 -0.00000 0.00000" xyz="0.00000 -0.02202 0.03242"/>
		<axis xyz="0.00000 0.00000 0.00000"/>
	</joint>
	<joint name="right_inner_knuckle_joint" type="continuous">
		<parent link="robotiq_arg2f_base_link"/>
		<child link="right_inner_knuckle"/>
		<dynamics damping="1.0" friction="0.0001"/>
		<origin rpy="0.00000 -0.00000 0.00000" xyz="0.00000 0.01270 0.06142"/>
		<axis xyz="1.00000 0.00000 0.00000"/>
	</joint>
</robot>
